Workbook

Sheet Dashboard
B2: Board Secretariat Dashboard
B3: Desert Horizon JV Board of Directors • Meetings, resolutions, DocuSign signatures and action follow-up • Demo data
B6: MEETINGS HELD | D6: RESOLUTIONS | G6: AWAITING SIGNATURE | J6: OPEN ACTIONS | L6: OVERDUE
B7: =COUNTIF('Meeting Calendar'!$L$5:$L$50,"Held") | D7: =COUNTA('Resolutions Register'!$A$5:$A$500) | G7: =COUNTIF('Resolutions Register'!$K$5:$K$500,"Awaiting Signatures") | J7: =COUNTIF('Action Log'!$F$5:$F$500,"<>Closed")-COUNTBLANK('Action Log'!$F$5:$F$500) | L7: =COUNTIF('Action Log'!$H$5:$H$500,">0")
B8: Board meetings in 2026 | D8: Meeting + circular | G8: Circular resolutions in DocuSign | J8: Open + in progress | L8: Past due date
B10: NEXT BOARD CYCLE
B11: Next meeting | C11: Meeting No. | E11: Type | G11: Papers deadline | I11: Days to papers | K11: Days to meeting
B12: =_xlfn.MINIFS('Meeting Calendar'!$B$5:$B$50,'Meeting Calendar'!$L$5:$L$50,"Scheduled") | C12: =INDEX('Meeting Calendar'!$A$5:$A$50,MATCH(B12,'Meeting Calendar'!$B$5:$B$50,0)) | E12: =INDEX('Meeting Calendar'!$C$5:$C$50,MATCH(B12,'Meeting Calendar'!$B$5:$B$50,0)) | G12: =B12-7 | I12: =G12-TODAY() | K12: =B12-TODAY()
B14: RESOLUTIONS BY CATEGORY | G14: RESOLUTIONS MIX
B15: Category | C15: Meeting | D15: Circular | E15: Total | F15: Awaiting
B16: Contracts & Subcontracts | C16: =COUNTIFS('Resolutions Register'!$E$5:$E$500,$B16,'Resolutions Register'!$D$5:$D$500,"Meeting") | D16: =COUNTIFS('Resolutions Register'!$E$5:$E$500,$B16,'Resolutions Register'!$D$5:$D$500,"Circular") | E16: =C16+D16 | F16: =COUNTIFS('Resolutions Register'!$E$5:$E$500,$B16,'Resolutions Register'!$K$5:$K$500,"Awaiting Signatures")
B17: Finance & Budget | C17: =COUNTIFS('Resolutions Register'!$E$5:$E$500,$B17,'Resolutions Register'!$D$5:$D$500,"Meeting") | D17: =COUNTIFS('Resolutions Register'!$E$5:$E$500,$B17,'Resolutions Register'!$D$5:$D$500,"Circular") | E17: =C17+D17 | F17: =COUNTIFS('Resolutions Register'!$E$5:$E$500,$B17,'Resolutions Register'!$K$5:$K$500,"Awaiting Signatures")
B18: Banking & LCs | C18: =COUNTIFS('Resolutions Register'!$E$5:$E$500,$B18,'Resolutions Register'!$D$5:$D$500,"Meeting") | D18: =COUNTIFS('Resolutions Register'!$E$5:$E$500,$B18,'Resolutions Register'!$D$5:$D$500,"Circular") | E18: =C18+D18 | F18: =COUNTIFS('Resolutions Register'!$E$5:$E$500,$B18,'Resolutions Register'!$K$5:$K$500,"Awaiting Signatures")
B19: HR & Appointments | C19: =COUNTIFS('Resolutions Register'!$E$5:$E$500,$B19,'Resolutions Register'!$D$5:$D$500,"Meeting") | D19: =COUNTIFS('Resolutions Register'!$E$5:$E$500,$B19,'Resolutions Register'!$D$5:$D$500,"Circular") | E19: =C19+D19 | F19: =COUNTIFS('Resolutions Register'!$E$5:$E$500,$B19,'Resolutions Register'!$K$5:$K$500,"Awaiting Signatures")
B20: Governance | C20: =COUNTIFS('Resolutions Register'!$E$5:$E$500,$B20,'Resolutions Register'!$D$5:$D$500,"Meeting") | D20: =COUNTIFS('Resolutions Register'!$E$5:$E$500,$B20,'Resolutions Register'!$D$5:$D$500,"Circular") | E20: =C20+D20 | F20: =COUNTIFS('Resolutions Register'!$E$5:$E$500,$B20,'Resolutions Register'!$K$5:$K$500,"Awaiting Signatures")
B21: HSE & Quality | C21: =COUNTIFS('Resolutions Register'!$E$5:$E$500,$B21,'Resolutions Register'!$D$5:$D$500,"Meeting") | D21: =COUNTIFS('Resolutions Register'!$E$5:$E$500,$B21,'Resolutions Register'!$D$5:$D$500,"Circular") | E21: =C21+D21 | F21: =COUNTIFS('Resolutions Register'!$E$5:$E$500,$B21,'Resolutions Register'!$K$5:$K$500,"Awaiting Signatures")
B22: Total | C22: =SUM(C16:C21) | D22: =SUM(D16:D21) | E22: =SUM(E16:E21) | F22: =SUM(F16:F21)
B25: BOARD ACTIONS BY OWNER | G25: ACTION STATUS BY OWNER
B26: Owner | C26: Open | D26: In Progress | E26: Closed | F26: Overdue
B27: Project Director | C27: =COUNTIFS('Action Log'!$D$5:$D$500,$B27,'Action Log'!$F$5:$F$500,"Open") | D27: =COUNTIFS('Action Log'!$D$5:$D$500,$B27,'Action Log'!$F$5:$F$500,"In Progress") | E27: =COUNTIFS('Action Log'!$D$5:$D$500,$B27,'Action Log'!$F$5:$F$500,"Closed") | F27: =COUNTIFS('Action Log'!$D$5:$D$500,$B27,'Action Log'!$H$5:$H$500,">0")
B28: Commercial Manager | C28: =COUNTIFS('Action Log'!$D$5:$D$500,$B28,'Action Log'!$F$5:$F$500,"Open") | D28: =COUNTIFS('Action Log'!$D$5:$D$500,$B28,'Action Log'!$F$5:$F$500,"In Progress") | E28: =COUNTIFS('Action Log'!$D$5:$D$500,$B28,'Action Log'!$F$5:$F$500,"Closed") | F28: =COUNTIFS('Action Log'!$D$5:$D$500,$B28,'Action Log'!$H$5:$H$500,">0")
B29: Finance Manager | C29: =COUNTIFS('Action Log'!$D$5:$D$500,$B29,'Action Log'!$F$5:$F$500,"Open") | D29: =COUNTIFS('Action Log'!$D$5:$D$500,$B29,'Action Log'!$F$5:$F$500,"In Progress") | E29: =COUNTIFS('Action Log'!$D$5:$D$500,$B29,'Action Log'!$F$5:$F$500,"Closed") | F29: =COUNTIFS('Action Log'!$D$5:$D$500,$B29,'Action Log'!$H$5:$H$500,">0")
B30: HR Manager | C30: =COUNTIFS('Action Log'!$D$5:$D$500,$B30,'Action Log'!$F$5:$F$500,"Open") | D30: =COUNTIFS('Action Log'!$D$5:$D$500,$B30,'Action Log'!$F$5:$F$500,"In Progress") | E30: =COUNTIFS('Action Log'!$D$5:$D$500,$B30,'Action Log'!$F$5:$F$500,"Closed") | F30: =COUNTIFS('Action Log'!$D$5:$D$500,$B30,'Action Log'!$H$5:$H$500,">0")
B31: HSE Director | C31: =COUNTIFS('Action Log'!$D$5:$D$500,$B31,'Action Log'!$F$5:$F$500,"Open") | D31: =COUNTIFS('Action Log'!$D$5:$D$500,$B31,'Action Log'!$F$5:$F$500,"In Progress") | E31: =COUNTIFS('Action Log'!$D$5:$D$500,$B31,'Action Log'!$F$5:$F$500,"Closed") | F31: =COUNTIFS('Action Log'!$D$5:$D$500,$B31,'Action Log'!$H$5:$H$500,">0")
B32: Board Secretary | C32: =COUNTIFS('Action Log'!$D$5:$D$500,$B32,'Action Log'!$F$5:$F$500,"Open") | D32: =COUNTIFS('Action Log'!$D$5:$D$500,$B32,'Action Log'!$F$5:$F$500,"In Progress") | E32: =COUNTIFS('Action Log'!$D$5:$D$500,$B32,'Action Log'!$F$5:$F$500,"Closed") | F32: =COUNTIFS('Action Log'!$D$5:$D$500,$B32,'Action Log'!$H$5:$H$500,">0")
B33: Total | C33: =SUM(C27:C32) | D33: =SUM(D27:D32) | E33: =SUM(E27:E32) | F33: =SUM(F27:F32)
B36: CIRCULAR RESOLUTIONS AWAITING DOCUSIGN SIGNATURES
B37: Subject | F37: Resolution No. | H37: Circulated | J37: Signed | L37: Days waiting
B38: =IFERROR(INDEX('Resolutions Register'!$F$5:$F$500,MATCH(1,'Resolutions Register'!$M$5:$M$500,0)),"") | F38: =IFERROR(INDEX('Resolutions Register'!$A$5:$A$500,MATCH(1,'Resolutions Register'!$M$5:$M$500,0)),"") | H38: =IFERROR(INDEX('Resolutions Register'!$B$5:$B$500,MATCH(1,'Resolutions Register'!$M$5:$M$500,0)),"") | J38: =IFERROR(INDEX('Resolutions Register'!$H$5:$H$500,MATCH(1,'Resolutions Register'!$M$5:$M$500,0))&" of "&INDEX('Resolutions Register'!$G$5:$G$500,MATCH(1,'Resolutions Register'!$M$5:$M$500,0)),"") | L38: =IFERROR(TODAY()-H38,"")
B39: =IFERROR(INDEX('Resolutions Register'!$F$5:$F$500,MATCH(2,'Resolutions Register'!$M$5:$M$500,0)),"") | F39: =IFERROR(INDEX('Resolutions Register'!$A$5:$A$500,MATCH(2,'Resolutions Register'!$M$5:$M$500,0)),"") | H39: =IFERROR(INDEX('Resolutions Register'!$B$5:$B$500,MATCH(2,'Resolutions Register'!$M$5:$M$500,0)),"") | J39: =IFERROR(INDEX('Resolutions Register'!$H$5:$H$500,MATCH(2,'Resolutions Register'!$M$5:$M$500,0))&" of "&INDEX('Resolutions Register'!$G$5:$G$500,MATCH(2,'Resolutions Register'!$M$5:$M$500,0)),"") | L39: =IFERROR(TODAY()-H39,"")
B40: =IFERROR(INDEX('Resolutions Register'!$F$5:$F$500,MATCH(3,'Resolutions Register'!$M$5:$M$500,0)),"") | F40: =IFERROR(INDEX('Resolutions Register'!$A$5:$A$500,MATCH(3,'Resolutions Register'!$M$5:$M$500,0)),"") | H40: =IFERROR(INDEX('Resolutions Register'!$B$5:$B$500,MATCH(3,'Resolutions Register'!$M$5:$M$500,0)),"") | J40: =IFERROR(INDEX('Resolutions Register'!$H$5:$H$500,MATCH(3,'Resolutions Register'!$M$5:$M$500,0))&" of "&INDEX('Resolutions Register'!$G$5:$G$500,MATCH(3,'Resolutions Register'!$M$5:$M$500,0)),"") | L40: =IFERROR(TODAY()-H40,"")
B41: =IFERROR(INDEX('Resolutions Register'!$F$5:$F$500,MATCH(4,'Resolutions Register'!$M$5:$M$500,0)),"") | F41: =IFERROR(INDEX('Resolutions Register'!$A$5:$A$500,MATCH(4,'Resolutions Register'!$M$5:$M$500,0)),"") | H41: =IFERROR(INDEX('Resolutions Register'!$B$5:$B$500,MATCH(4,'Resolutions Register'!$M$5:$M$500,0)),"") | J41: =IFERROR(INDEX('Resolutions Register'!$H$5:$H$500,MATCH(4,'Resolutions Register'!$M$5:$M$500,0))&" of "&INDEX('Resolutions Register'!$G$5:$G$500,MATCH(4,'Resolutions Register'!$M$5:$M$500,0)),"") | L41: =IFERROR(TODAY()-H41,"")
B42: =IFERROR(INDEX('Resolutions Register'!$F$5:$F$500,MATCH(5,'Resolutions Register'!$M$5:$M$500,0)),"") | F42: =IFERROR(INDEX('Resolutions Register'!$A$5:$A$500,MATCH(5,'Resolutions Register'!$M$5:$M$500,0)),"") | H42: =IFERROR(INDEX('Resolutions Register'!$B$5:$B$500,MATCH(5,'Resolutions Register'!$M$5:$M$500,0)),"") | J42: =IFERROR(INDEX('Resolutions Register'!$H$5:$H$500,MATCH(5,'Resolutions Register'!$M$5:$M$500,0))&" of "&INDEX('Resolutions Register'!$G$5:$G$500,MATCH(5,'Resolutions Register'!$M$5:$M$500,0)),"") | L42: =IFERROR(TODAY()-H42,"")

Sheet Board Members
A1: Board Members
A2: Desert Horizon JV • JV of Rimal Contracting Co. (KSA) & Anatolia Yapı A.Ş. (Türkiye) • Demo data
A4: Member ID | B4: Name | C4: Board Role | D4: Partner Company | E4: Attendance 2026
A5: BM-01 | B5: Eng. Khalid Al-Mansour | C5: Chairman | D5: Rimal Contracting Co. | E5: =Attendance!I5
A6: BM-02 | B6: Mr. Emre Kaya | C6: Vice Chairman | D6: Anatolia Yapı A.Ş. | E6: =Attendance!I6
A7: BM-03 | B7: Mr. Saud Al-Harbi | C7: Board Member | D7: Rimal Contracting Co. | E7: =Attendance!I7
A8: BM-04 | B8: Mr. Burak Demir | C8: Board Member | D8: Anatolia Yapı A.Ş. | E8: =Attendance!I8
A9: BM-05 | B9: Ms. Layla Al-Zahrani | C9: Board Member | D9: Rimal Contracting Co. | E9: =Attendance!I9
A10: BM-06 | B10: Mr. Selim Aydın | C10: Board Member | D10: Anatolia Yapı A.Ş. | E10: =Attendance!I10
A11: SEC | B11: Board Secretariat | C11: Secretary (non-voting) | D11: Desert Horizon JV | E11: —

Sheet Meeting Calendar
A1: Board Meeting Calendar 2026
A2: Desert Horizon JV • JV of Rimal Contracting Co. (KSA) & Anatolia Yapı A.Ş. (Türkiye) • Demo data • Papers deadline = 7 days before meeting
A4: Meeting No. | B4: Meeting Date | C4: Type | D4: Venue / Mode | E4: Agenda Items | F4: Members Present | G4: Quorum | H4: Papers Deadline | I4: Papers Circulated | J4: Minutes Issued | K4: Minutes Signed | L4: Status
A5: BOD-2026-01 | B5: 46044 | C5: Ordinary | D5: Riyadh HQ | E5: 9 | F5: 6 | G5: =IF(F5="","",IF(F5>=4,"Quorate","No quorum")) | H5: =B5-7 | I5: 46036 | J5: 46050 | K5: 46059 | L5: Held
A6: BOD-2026-02 | B6: 46100 | C6: Ordinary | D6: Site Office | E6: 9 | F6: 6 | G6: =IF(F6="","",IF(F6>=4,"Quorate","No quorum")) | H6: =B6-7 | I6: 46094 | J6: 46106 | K6: 46115 | L6: Held
A7: BOD-2026-03 | B7: 46120 | C7: Extraordinary | D7: Virtual (Teams) | E7: 10 | F7: 6 | G7: =IF(F7="","",IF(F7>=4,"Quorate","No quorum")) | H7: =B7-7 | I7: 46112 | J7: 46124 | K7: 46129 | L7: Held
A8: BOD-2026-04 | B8: 46163 | C8: Ordinary | D8: Istanbul Office | E8: 8 | F8: 5 | G8: =IF(F8="","",IF(F8>=4,"Quorate","No quorum")) | H8: =B8-7 | I8: 46155 | J8: 46169 | K8: 46174 | L8: Held
A9: BOD-2026-05 | B9: 46226 | C9: Ordinary | D9: Riyadh HQ | E9: 7 | F9: 6 | G9: =IF(F9="","",IF(F9>=4,"Quorate","No quorum")) | H9: =B9-7 | I9: 46220 | J9: 46229 | K9: 46236 | L9: Held
A10: BOD-2026-06 | B10: 46289 | C10: Ordinary | D10: Site Office | E10: 10 | F10: 6 | G10: =IF(F10="","",IF(F10>=4,"Quorate","No quorum")) | H10: =B10-7 | I10: 46282 | J10: 46292 | K10: 46299 | L10: Held
A11: BOD-2026-07 | B11: 46345 | C11: Ordinary | D11: Riyadh HQ | E11: 10 | G11: =IF(F11="","",IF(F11>=4,"Quorate","No quorum")) | H11: =B11-7 | L11: Scheduled
A12: BOD-2026-08 | B12: 46373 | C12: Extraordinary | D12: Virtual (Teams) | E12: 9 | G12: =IF(F12="","",IF(F12>=4,"Quorate","No quorum")) | H12: =B12-7 | L12: Scheduled

Sheet Resolutions Register
A1: Board Resolutions Register
A2: Desert Horizon JV • JV of Rimal Contracting Co. (KSA) & Anatolia Yapı A.Ş. (Türkiye) • Demo data • Circular resolutions signed via DocuSign
A4: Resolution No. | B4: Date | C4: Meeting Ref | D4: Type | E4: Category | F4: Subject | G4: Signatories Req. | H4: Signed | I4: Signed % | J4: DocuSign Envelope | K4: Status | L4: Effective Date | M4: Pending #
A5: BR-2026-001 | B5: 46044 | C5: BOD-2026-01 | D5: Meeting | E5: HSE & Quality | F5: Approval of emergency response plan | G5: 6 | H5: 6 | I5: =IFERROR(H5/G5,0) | J5: DS-124352 | K5: Completed | L5: 46059 | M5: =IF(K5="Awaiting Signatures",COUNTIF($K$5:K5,"Awaiting Signatures"),"")
A6: BR-2026-002 | B6: 46044 | C6: BOD-2026-01 | D6: Meeting | E6: Finance & Budget | F6: Approval of revised project budget | G6: 6 | H6: 6 | I6: =IFERROR(H6/G6,0) | J6: DS-230943 | K6: Completed | L6: 46059 | M6: =IF(K6="Awaiting Signatures",COUNTIF($K$5:K6,"Awaiting Signatures"),"")
A7: BR-2026-003 | B7: 46044 | C7: BOD-2026-01 | D7: Meeting | E7: Contracts & Subcontracts | F7: Extension of equipment rental agreement | G7: 6 | H7: 6 | I7: =IFERROR(H7/G7,0) | J7: DS-268924 | K7: Completed | L7: 46059 | M7: =IF(K7="Awaiting Signatures",COUNTIF($K$5:K7,"Awaiting Signatures"),"")
A8: BR-2026-004 | B8: 46064 | C8: Circular | D8: Circular | E8: Banking & LCs | F8: Opening of letter of credit for TBM spares | G8: 6 | H8: 6 | I8: =IFERROR(H8/G8,0) | J8: DS-271008 | K8: Completed | L8: 46072 | M8: =IF(K8="Awaiting Signatures",COUNTIF($K$5:K8,"Awaiting Signatures"),"")
A9: BR-2026-005 | B9: 46079 | C9: Circular | D9: Circular | E9: Contracts & Subcontracts | F9: Award of muck-removal subcontract | G9: 6 | H9: 6 | I9: =IFERROR(H9/G9,0) | J9: DS-719203 | K9: Completed | L9: 46082 | M9: =IF(K9="Awaiting Signatures",COUNTIF($K$5:K9,"Awaiting Signatures"),"")
A10: BR-2026-006 | B10: 46100 | C10: BOD-2026-02 | D10: Meeting | E10: HR & Appointments | F10: Approval of staff incentive scheme | G10: 6 | H10: 6 | I10: =IFERROR(H10/G10,0) | J10: DS-258437 | K10: Completed | L10: 46115 | M10: =IF(K10="Awaiting Signatures",COUNTIF($K$5:K10,"Awaiting Signatures"),"")
A11: BR-2026-007 | B11: 46100 | C11: BOD-2026-02 | D11: Meeting | E11: Finance & Budget | F11: Approval of revised project budget | G11: 6 | H11: 6 | I11: =IFERROR(H11/G11,0) | J11: DS-592769 | K11: Completed | L11: 46115 | M11: =IF(K11="Awaiting Signatures",COUNTIF($K$5:K11,"Awaiting Signatures"),"")
A12: BR-2026-008 | B12: 46100 | C12: BOD-2026-02 | D12: Meeting | E12: Finance & Budget | F12: Approval of revised project budget | G12: 6 | H12: 6 | I12: =IFERROR(H12/G12,0) | J12: DS-918161 | K12: Completed | L12: 46115 | M12: =IF(K12="Awaiting Signatures",COUNTIF($K$5:K12,"Awaiting Signatures"),"")
A13: BR-2026-009 | B13: 46100 | C13: BOD-2026-02 | D13: Meeting | E13: Finance & Budget | F13: Approval of quarterly financial statements | G13: 6 | H13: 6 | I13: =IFERROR(H13/G13,0) | J13: DS-806524 | K13: Completed | L13: 46115 | M13: =IF(K13="Awaiting Signatures",COUNTIF($K$5:K13,"Awaiting Signatures"),"")
A14: BR-2026-010 | B14: 46100 | C14: BOD-2026-02 | D14: Meeting | E14: HSE & Quality | F14: Endorsement of quality audit findings | G14: 6 | H14: 6 | I14: =IFERROR(H14/G14,0) | J14: DS-865206 | K14: Completed | L14: 46115 | M14: =IF(K14="Awaiting Signatures",COUNTIF($K$5:K14,"Awaiting Signatures"),"")
A15: BR-2026-011 | B15: 46120 | C15: BOD-2026-03 | D15: Meeting | E15: Contracts & Subcontracts | F15: Extension of equipment rental agreement | G15: 6 | H15: 6 | I15: =IFERROR(H15/G15,0) | J15: DS-686093 | K15: Completed | L15: 46129 | M15: =IF(K15="Awaiting Signatures",COUNTIF($K$5:K15,"Awaiting Signatures"),"")
A16: BR-2026-012 | B16: 46120 | C16: BOD-2026-03 | D16: Meeting | E16: HR & Appointments | F16: Approval of manpower plan | G16: 6 | H16: 6 | I16: =IFERROR(H16/G16,0) | J16: DS-457806 | K16: Completed | L16: 46129 | M16: =IF(K16="Awaiting Signatures",COUNTIF($K$5:K16,"Awaiting Signatures"),"")
... A36: BR-2026-032 | B36: 46289 | C36: BOD-2026-06 | D36: Meeting | E36: Governance | F36: Adoption of board calendar | G36: 6 | H36: 6 | I36: =IFERROR(H36/G36,0) | J36: DS-526785 | K36: Completed | L36: 46299 | M36: =IF(K36="Awaiting Signatures",COUNTIF($K$5:K36,"Awaiting Signatures"),"")
A37: BR-2026-033 | B37: 46296 | C37: Circular | D37: Circular | E37: Banking & LCs | F37: Renewal of performance bond | G37: 6 | H37: 4 | I37: =IFERROR(H37/G37,0) | J37: DS-944399 | K37: Awaiting Signatures | M37: =IF(K37="Awaiting Signatures",COUNTIF($K$5:K37,"Awaiting Signatures"),"")
A38: BR-2026-034 | B38: 46301 | C38: Circular | D38: Circular | E38: Finance & Budget | F38: Approval of Q3 cash-flow forecast | G38: 6 | H38: 4 | I38: =IFERROR(H38/G38,0) | J38: DS-911510 | K38: Awaiting Signatures | M38: =IF(K38="Awaiting Signatures",COUNTIF($K$5:K38,"Awaiting Signatures"),"")
A39: BR-2026-035 | B39: 46306 | C39: Circular | D39: Circular | E39: Contracts & Subcontracts | F39: Award of tunnel ventilation subcontract | G39: 6 | H39: 5 | I39: =IFERROR(H39/G39,0) | J39: DS-606643 | K39: Awaiting Signatures | M39: =IF(K39="Awaiting Signatures",COUNTIF($K$5:K39,"Awaiting Signatures"),"")

Sheet Action Log
A1: Board Action Log
A2: Desert Horizon JV • JV of Rimal Contracting Co. (KSA) & Anatolia Yapı A.Ş. (Türkiye) • Demo data • Days overdue calculated against today
A4: Action ID | B4: Meeting Ref | C4: Action | D4: Owner | E4: Due Date | F4: Status | G4: Closed Date | H4: Days Overdue
A5: ACT-001 | B5: BOD-2026-01 | C5: Submit claim status report to the client | D5: Finance Manager | E5: 46074 | F5: Closed | G5: 46072 | H5: =IF(AND(F5<>"Closed",E5<TODAY()),TODAY()-E5,"")
A6: ACT-002 | B6: BOD-2026-01 | C6: Present insurance renewal options | D6: Project Director | E6: 46058 | F6: Closed | G6: 46054 | H6: =IF(AND(F6<>"Closed",E6<TODAY()),TODAY()-E6,"")
A7: ACT-003 | B7: BOD-2026-01 | C7: Present TBM progress recovery plan | D7: Board Secretary | E7: 46074 | F7: Closed | G7: 46070 | H7: =IF(AND(F7<>"Closed",E7<TODAY()),TODAY()-E7,"")
A8: ACT-004 | B8: BOD-2026-01 | C8: Submit claim status report to the client | D8: HSE Director | E8: 46089 | F8: Closed | G8: 46085 | H8: =IF(AND(F8<>"Closed",E8<TODAY()),TODAY()-E8,"")
A9: ACT-005 | B9: BOD-2026-01 | C9: Report on manpower localisation | D9: Commercial Manager | E9: 46089 | F9: Closed | G9: 46086 | H9: =IF(AND(F9<>"Closed",E9<TODAY()),TODAY()-E9,"")
A10: ACT-006 | B10: BOD-2026-02 | C10: Share bank signatory forms with both partners | D10: Commercial Manager | E10: 46145 | F10: Closed | G10: 46146 | H10: =IF(AND(F10<>"Closed",E10<TODAY()),TODAY()-E10,"")
A11: ACT-007 | B11: BOD-2026-02 | C11: Submit revised cash-flow to the board | D11: HR Manager | E11: 46130 | F11: Closed | G11: 46135 | H11: =IF(AND(F11<>"Closed",E11<TODAY()),TODAY()-E11,"")
A12: ACT-008 | B12: BOD-2026-02 | C12: Submit revised cash-flow to the board | D12: Finance Manager | E12: 46121 | F12: In Progress | H12: =IF(AND(F12<>"Closed",E12<TODAY()),TODAY()-E12,"")
A13: ACT-009 | B13: BOD-2026-02 | C13: Present insurance renewal options | D13: Finance Manager | E13: 46130 | F13: Closed | G13: 46133 | H13: =IF(AND(F13<>"Closed",E13<TODAY()),TODAY()-E13,"")
A14: ACT-010 | B14: BOD-2026-02 | C14: Present TBM progress recovery plan | D14: Commercial Manager | E14: 46145 | F14: Closed | G14: 46141 | H14: =IF(AND(F14<>"Closed",E14<TODAY()),TODAY()-E14,"")
A15: ACT-011 | B15: BOD-2026-02 | C15: Submit revised cash-flow to the board | D15: Board Secretary | E15: 46114 | F15: Closed | G15: 46110 | H15: =IF(AND(F15<>"Closed",E15<TODAY()),TODAY()-E15,"")
A16: ACT-012 | B16: BOD-2026-02 | C16: Circulate signed subcontract to partners | D16: Board Secretary | E16: 46145 | F16: Closed | G16: 46140 | H16: =IF(AND(F16<>"Closed",E16<TODAY()),TODAY()-E16,"")
A17: ACT-013 | B17: BOD-2026-03 | C17: Present insurance renewal options | D17: HR Manager | E17: 46141 | F17: Closed | G17: 46140 | H17: =IF(AND(F17<>"Closed",E17<TODAY()),TODAY()-E17,"")
A18: ACT-014 | B18: BOD-2026-03 | C18: Present TBM progress recovery plan | D18: HR Manager | E18: 46141 | F18: Closed | G18: 46137 | H18: =IF(AND(F18<>"Closed",E18<TODAY()),TODAY()-E18,"")
A19: ACT-015 | B19: BOD-2026-03 | C19: Submit revised cash-flow to the board | D19: HSE Director | E19: 46141 | F19: Closed | G19: 46143 | H19: =IF(AND(F19<>"Closed",E19<TODAY()),TODAY()-E19,"")
A20: ACT-016 | B20: BOD-2026-03 | C20: Present insurance renewal options | D20: HR Manager | E20: 46134 | F20: Closed | G20: 46128 | H20: =IF(AND(F20<>"Closed",E20<TODAY()),TODAY()-E20,"")
A21: ACT-017 | B21: BOD-2026-03 | C21: Present TBM progress recovery plan | D21: Board Secretary | E21: 46134 | F21: Closed | G21: 46137 | H21: =IF(AND(F21<>"Closed",E21<TODAY()),TODAY()-E21,"")
A22: ACT-018 | B22: BOD-2026-03 | C22: Prepare board calendar for next year | D22: Finance Manager | E22: 46141 | F22: Closed | G22: 46146 | H22: =IF(AND(F22<>"Closed",E22<TODAY()),TODAY()-E22,"")
A23: ACT-019 | B23: BOD-2026-03 | C23: Share bank signatory forms with both partners | D23: Board Secretary | E23: 46134 | F23: Closed | G23: 46130 | H23: =IF(AND(F23<>"Closed",E23<TODAY()),TODAY()-E23,"")
A24: ACT-020 | B24: BOD-2026-04 | C24: Circulate signed subcontract to partners | D24: HSE Director | E24: 46208 | F24: In Progress | H24: =IF(AND(F24<>"Closed",E24<TODAY()),TODAY()-E24,"")
A25: ACT-021 | B25: BOD-2026-04 | C25: Report on manpower localisation | D25: HSE Director | E25: 46177 | F25: Closed | G25: 46182 | H25: =IF(AND(F25<>"Closed",E25<TODAY()),TODAY()-E25,"")
A26: ACT-022 | B26: BOD-2026-04 | C26: Share HSE statistics with lessons learned | D26: HSE Director | E26: 46193 | F26: Closed | G26: 46196 | H26: =IF(AND(F26<>"Closed",E26<TODAY()),TODAY()-E26,"")
A27: ACT-023 | B27: BOD-2026-04 | C27: Update delegation of authority in Oracle | D27: Finance Manager | E27: 46184 | F27: Closed | G27: 46183 | H27: =IF(AND(F27<>"Closed",E27<TODAY()),TODAY()-E27,"")
A28: ACT-024 | B28: BOD-2026-04 | C28: Circulate signed subcontract to partners | D28: Project Director | E28: 46177 | F28: Closed | G28: 46177 | H28: =IF(AND(F28<>"Closed",E28<TODAY()),TODAY()-E28,"")
A29: ACT-025 | B29: BOD-2026-04 | C29: Share HSE statistics with lessons learned | D29: HSE Director | E29: 46177 | F29: Closed | G29: 46178 | H29: =IF(AND(F29<>"Closed",E29<TODAY()),TODAY()-E29,"")
A30: ACT-026 | B30: BOD-2026-04 | C30: Close internal audit observations | D30: HR Manager | E30: 46177 | F30: Closed | G30: 46182 | H30: =IF(AND(F30<>"Closed",E30<TODAY()),TODAY()-E30,"")
A31: ACT-027 | B31: BOD-2026-05 | C31: Submit revised cash-flow to the board | D31: Project Director | E31: 46271 | F31: Closed | G31: 46268 | H31: =IF(AND(F31<>"Closed",E31<TODAY()),TODAY()-E31,"")
A32: ACT-028 | B32: BOD-2026-05 | C32: Share bank signatory forms with both partners | D32: Board Secretary | E32: 46271 | F32: Closed | G32: 46268 | H32: =IF(AND(F32<>"Closed",E32<TODAY()),TODAY()-E32,"")
A33: ACT-029 | B33: BOD-2026-05 | C33: Close internal audit observations | D33: Commercial Manager | E33: 46271 | F33: In Progress | H33: =IF(AND(F33<>"Closed",E33<TODAY()),TODAY()-E33,"")
A34: ACT-030 | B34: BOD-2026-05 | C34: Report on manpower localisation | D34: HR Manager | E34: 46271 | F34: In Progress | H34: =IF(AND(F34<>"Closed",E34<TODAY()),TODAY()-E34,"")
A35: ACT-031 | B35: BOD-2026-05 | C35: Circulate signed subcontract to partners | D35: Project Director | E35: 46247 | F35: Closed | G35: 46251 | H35: =IF(AND(F35<>"Closed",E35<TODAY()),TODAY()-E35,"")
A36: ACT-032 | B36: BOD-2026-05 | C36: Close internal audit observations | D36: Finance Manager | E36: 46271 | F36: In Progress | H36: =IF(AND(F36<>"Closed",E36<TODAY()),TODAY()-E36,"")
A37: ACT-033 | B37: BOD-2026-05 | C37: Submit claim status report to the client | D37: HSE Director | E37: 46247 | F37: Closed | G37: 46251 | H37: =IF(AND(F37<>"Closed",E37<TODAY()),TODAY()-E37,"")
A38: ACT-034 | B38: BOD-2026-05 | C38: Present insurance renewal options | D38: Finance Manager | E38: 46256 | F38: Closed | G38: 46257 | H38: =IF(AND(F38<>"Closed",E38<TODAY()),TODAY()-E38,"")
A39: ACT-035 | B39: BOD-2026-06 | C39: Report on manpower localisation | D39: Commercial Manager | E39: 46303 | F39: In Progress | H39: =IF(AND(F39<>"Closed",E39<TODAY()),TODAY()-E39,"")
A40: ACT-036 | B40: BOD-2026-06 | C40: Update risk register and top-10 risks | D40: Commercial Manager | E40: 46319 | F40: In Progress | H40: =IF(AND(F40<>"Closed",E40<TODAY()),TODAY()-E40,"")
A41: ACT-037 | B41: BOD-2026-06 | C41: Circulate signed subcontract to partners | D41: HSE Director | E41: 46303 | F41: In Progress | H41: =IF(AND(F41<>"Closed",E41<TODAY()),TODAY()-E41,"")
...

Sheet Attendance
A1: Board Attendance Matrix 2026
A2: Desert Horizon JV • JV of Rimal Contracting Co. (KSA) & Anatolia Yapı A.Ş. (Türkiye) • Demo data • P = Present, A = Apology
A4: Member | B4: Role | C4: BOD-01 | D4: BOD-02 | E4: BOD-03 | F4: BOD-04 | G4: BOD-05 | H4: BOD-06 | I4: Attendance %
A5: Eng. Khalid Al-Mansour | B5: Chairman | C5: P | D5: P | E5: P | F5: P | G5: P | H5: P | I5: =COUNTIF(C5:H5,"P")/COUNTA(C5:H5)
A6: Mr. Emre Kaya | B6: Vice Chairman | C6: P | D6: P | E6: P | F6: P | G6: P | H6: P | I6: =COUNTIF(C6:H6,"P")/COUNTA(C6:H6)
A7: Mr. Saud Al-Harbi | B7: Board Member | C7: P | D7: P | E7: P | F7: P | G7: P | H7: P | I7: =COUNTIF(C7:H7,"P")/COUNTA(C7:H7)
A8: Mr. Burak Demir | B8: Board Member | C8: P | D8: P | E8: P | F8: P | G8: P | H8: P | I8: =COUNTIF(C8:H8,"P")/COUNTA(C8:H8)
A9: Ms. Layla Al-Zahrani | B9: Board Member | C9: P | D9: P | E9: P | F9: A | G9: P | H9: P | I9: =COUNTIF(C9:H9,"P")/COUNTA(C9:H9)
A10: Mr. Selim Aydın | B10: Board Member | C10: P | D10: P | E10: P | F10: P | G10: P | H10: P | I10: =COUNTIF(C10:H10,"P")/COUNTA(C10:H10)
