Workbook

Sheet Dashboard
B2: Document Control Dashboard
B3: Coastal Tunnel Package (CTP) • Desert Horizon JV • Reviewer: Meridian Engineering Partners • Demo data
B6: TOTAL DOCUMENTS | E6: APPROVED (A + B) | H6: UNDER REVIEW | K6: RESUBMIT (C + D)
B7: =COUNTA('Document Register'!$A$5:$A$2000) | E7: =COUNTIF('Document Register'!$I$5:$I$2000,"Code A*")+COUNTIF('Document Register'!$I$5:$I$2000,"Code B*") | H7: =COUNTIF('Document Register'!$I$5:$I$2000,"Under Review") | K7: =COUNTIF('Document Register'!$I$5:$I$2000,"Code C*")+COUNTIF('Document Register'!$I$5:$I$2000,"Code D*")
B8: Registered submissions | E8: Cleared for use | H8: =COUNTIFS('Document Register'!$I$5:$I$2000,"Under Review",'Document Register'!$K$5:$K$2000,">14")&" overdue (> 14 days)" | K8: Revise or new submission
B10: REVIEW STATUS BY DOCUMENT TYPE | I10: OVERALL REVIEW STATUS
B11: Document Type | C11: Code A | D11: Code B | E11: Code C | F11: Code D | G11: In Review | H11: Total
B12: Drawing | C12: =COUNTIFS('Document Register'!$C$5:$C$2000,$B12,'Document Register'!$I$5:$I$2000,"Code A*") | D12: =COUNTIFS('Document Register'!$C$5:$C$2000,$B12,'Document Register'!$I$5:$I$2000,"Code B*") | E12: =COUNTIFS('Document Register'!$C$5:$C$2000,$B12,'Document Register'!$I$5:$I$2000,"Code C*") | F12: =COUNTIFS('Document Register'!$C$5:$C$2000,$B12,'Document Register'!$I$5:$I$2000,"Code D*") | G12: =COUNTIFS('Document Register'!$C$5:$C$2000,$B12,'Document Register'!$I$5:$I$2000,"Under Review") | H12: =SUM(C12:G12)
B13: Method Statement | C13: =COUNTIFS('Document Register'!$C$5:$C$2000,$B13,'Document Register'!$I$5:$I$2000,"Code A*") | D13: =COUNTIFS('Document Register'!$C$5:$C$2000,$B13,'Document Register'!$I$5:$I$2000,"Code B*") | E13: =COUNTIFS('Document Register'!$C$5:$C$2000,$B13,'Document Register'!$I$5:$I$2000,"Code C*") | F13: =COUNTIFS('Document Register'!$C$5:$C$2000,$B13,'Document Register'!$I$5:$I$2000,"Code D*") | G13: =COUNTIFS('Document Register'!$C$5:$C$2000,$B13,'Document Register'!$I$5:$I$2000,"Under Review") | H13: =SUM(C13:G13)
B14: Material Submittal | C14: =COUNTIFS('Document Register'!$C$5:$C$2000,$B14,'Document Register'!$I$5:$I$2000,"Code A*") | D14: =COUNTIFS('Document Register'!$C$5:$C$2000,$B14,'Document Register'!$I$5:$I$2000,"Code B*") | E14: =COUNTIFS('Document Register'!$C$5:$C$2000,$B14,'Document Register'!$I$5:$I$2000,"Code C*") | F14: =COUNTIFS('Document Register'!$C$5:$C$2000,$B14,'Document Register'!$I$5:$I$2000,"Code D*") | G14: =COUNTIFS('Document Register'!$C$5:$C$2000,$B14,'Document Register'!$I$5:$I$2000,"Under Review") | H14: =SUM(C14:G14)
B15: Inspection Report | C15: =COUNTIFS('Document Register'!$C$5:$C$2000,$B15,'Document Register'!$I$5:$I$2000,"Code A*") | D15: =COUNTIFS('Document Register'!$C$5:$C$2000,$B15,'Document Register'!$I$5:$I$2000,"Code B*") | E15: =COUNTIFS('Document Register'!$C$5:$C$2000,$B15,'Document Register'!$I$5:$I$2000,"Code C*") | F15: =COUNTIFS('Document Register'!$C$5:$C$2000,$B15,'Document Register'!$I$5:$I$2000,"Code D*") | G15: =COUNTIFS('Document Register'!$C$5:$C$2000,$B15,'Document Register'!$I$5:$I$2000,"Under Review") | H15: =SUM(C15:G15)
B16: Procedure | C16: =COUNTIFS('Document Register'!$C$5:$C$2000,$B16,'Document Register'!$I$5:$I$2000,"Code A*") | D16: =COUNTIFS('Document Register'!$C$5:$C$2000,$B16,'Document Register'!$I$5:$I$2000,"Code B*") | E16: =COUNTIFS('Document Register'!$C$5:$C$2000,$B16,'Document Register'!$I$5:$I$2000,"Code C*") | F16: =COUNTIFS('Document Register'!$C$5:$C$2000,$B16,'Document Register'!$I$5:$I$2000,"Code D*") | G16: =COUNTIFS('Document Register'!$C$5:$C$2000,$B16,'Document Register'!$I$5:$I$2000,"Under Review") | H16: =SUM(C16:G16)
B17: Calculation | C17: =COUNTIFS('Document Register'!$C$5:$C$2000,$B17,'Document Register'!$I$5:$I$2000,"Code A*") | D17: =COUNTIFS('Document Register'!$C$5:$C$2000,$B17,'Document Register'!$I$5:$I$2000,"Code B*") | E17: =COUNTIFS('Document Register'!$C$5:$C$2000,$B17,'Document Register'!$I$5:$I$2000,"Code C*") | F17: =COUNTIFS('Document Register'!$C$5:$C$2000,$B17,'Document Register'!$I$5:$I$2000,"Code D*") | G17: =COUNTIFS('Document Register'!$C$5:$C$2000,$B17,'Document Register'!$I$5:$I$2000,"Under Review") | H17: =SUM(C17:G17)
B18: Total | C18: =SUM(C12:C17) | D18: =SUM(D12:D17) | E18: =SUM(E12:E17) | F18: =SUM(F12:F17) | G18: =SUM(G12:G17) | H18: =SUM(H12:H17)
B24: DOCUMENTS BY DISCIPLINE | I24: APPROVED VS RESUBMIT BY DISCIPLINE
B25: Discipline | C25: Approved | D25: In Review | E25: Resubmit | F25: Total
B26: Tunnelling | C26: =COUNTIFS('Document Register'!$D$5:$D$2000,$B26,'Document Register'!$I$5:$I$2000,"Code A*")+COUNTIFS('Document Register'!$D$5:$D$2000,$B26,'Document Register'!$I$5:$I$2000,"Code B*") | D26: =COUNTIFS('Document Register'!$D$5:$D$2000,$B26,'Document Register'!$I$5:$I$2000,"Under Review") | E26: =COUNTIFS('Document Register'!$D$5:$D$2000,$B26,'Document Register'!$I$5:$I$2000,"Code C*")+COUNTIFS('Document Register'!$D$5:$D$2000,$B26,'Document Register'!$I$5:$I$2000,"Code D*") | F26: =SUM(C26:E26)
B27: Civil | C27: =COUNTIFS('Document Register'!$D$5:$D$2000,$B27,'Document Register'!$I$5:$I$2000,"Code A*")+COUNTIFS('Document Register'!$D$5:$D$2000,$B27,'Document Register'!$I$5:$I$2000,"Code B*") | D27: =COUNTIFS('Document Register'!$D$5:$D$2000,$B27,'Document Register'!$I$5:$I$2000,"Under Review") | E27: =COUNTIFS('Document Register'!$D$5:$D$2000,$B27,'Document Register'!$I$5:$I$2000,"Code C*")+COUNTIFS('Document Register'!$D$5:$D$2000,$B27,'Document Register'!$I$5:$I$2000,"Code D*") | F27: =SUM(C27:E27)
B28: Geotechnical | C28: =COUNTIFS('Document Register'!$D$5:$D$2000,$B28,'Document Register'!$I$5:$I$2000,"Code A*")+COUNTIFS('Document Register'!$D$5:$D$2000,$B28,'Document Register'!$I$5:$I$2000,"Code B*") | D28: =COUNTIFS('Document Register'!$D$5:$D$2000,$B28,'Document Register'!$I$5:$I$2000,"Under Review") | E28: =COUNTIFS('Document Register'!$D$5:$D$2000,$B28,'Document Register'!$I$5:$I$2000,"Code C*")+COUNTIFS('Document Register'!$D$5:$D$2000,$B28,'Document Register'!$I$5:$I$2000,"Code D*") | F28: =SUM(C28:E28)
B29: MEP | C29: =COUNTIFS('Document Register'!$D$5:$D$2000,$B29,'Document Register'!$I$5:$I$2000,"Code A*")+COUNTIFS('Document Register'!$D$5:$D$2000,$B29,'Document Register'!$I$5:$I$2000,"Code B*") | D29: =COUNTIFS('Document Register'!$D$5:$D$2000,$B29,'Document Register'!$I$5:$I$2000,"Under Review") | E29: =COUNTIFS('Document Register'!$D$5:$D$2000,$B29,'Document Register'!$I$5:$I$2000,"Code C*")+COUNTIFS('Document Register'!$D$5:$D$2000,$B29,'Document Register'!$I$5:$I$2000,"Code D*") | F29: =SUM(C29:E29)
B30: HSE | C30: =COUNTIFS('Document Register'!$D$5:$D$2000,$B30,'Document Register'!$I$5:$I$2000,"Code A*")+COUNTIFS('Document Register'!$D$5:$D$2000,$B30,'Document Register'!$I$5:$I$2000,"Code B*") | D30: =COUNTIFS('Document Register'!$D$5:$D$2000,$B30,'Document Register'!$I$5:$I$2000,"Under Review") | E30: =COUNTIFS('Document Register'!$D$5:$D$2000,$B30,'Document Register'!$I$5:$I$2000,"Code C*")+COUNTIFS('Document Register'!$D$5:$D$2000,$B30,'Document Register'!$I$5:$I$2000,"Code D*") | F30: =SUM(C30:E30)
B31: Quality | C31: =COUNTIFS('Document Register'!$D$5:$D$2000,$B31,'Document Register'!$I$5:$I$2000,"Code A*")+COUNTIFS('Document Register'!$D$5:$D$2000,$B31,'Document Register'!$I$5:$I$2000,"Code B*") | D31: =COUNTIFS('Document Register'!$D$5:$D$2000,$B31,'Document Register'!$I$5:$I$2000,"Under Review") | E31: =COUNTIFS('Document Register'!$D$5:$D$2000,$B31,'Document Register'!$I$5:$I$2000,"Code C*")+COUNTIFS('Document Register'!$D$5:$D$2000,$B31,'Document Register'!$I$5:$I$2000,"Code D*") | F31: =SUM(C31:E31)

Sheet Search
A1: Document Search
A2: Type any part of a document number, title, type, discipline, transmittal or status in the yellow box
B4: Search: | D4: =IF($C$4="","Type to search",COUNT('Document Register'!$O$5:$O$2000)&" document(s) found")
A6: Document No. | B6: Title | C6: Type | D6: Discipline | E6: Rev | F6: Submitted | G6: Review Status | H6: File Location
A7: =IF($J7="","",INDEX('Document Register'!$A:$A,$J7)) | B7: =IF($J7="","",INDEX('Document Register'!$B:$B,$J7)) | C7: =IF($J7="","",INDEX('Document Register'!$C:$C,$J7)) | D7: =IF($J7="","",INDEX('Document Register'!$D:$D,$J7)) | E7: =IF($J7="","",INDEX('Document Register'!$E:$E,$J7)) | F7: =IF($J7="","",INDEX('Document Register'!$F:$F,$J7)) | G7: =IF($J7="","",INDEX('Document Register'!$I:$I,$J7)) | H7: =IF($J7="","",INDEX('Document Register'!$M:$M,$J7)) | J7: =IFERROR(SMALL('Document Register'!$O$5:$O$2000,ROW()-6),"")
A8: =IF($J8="","",INDEX('Document Register'!$A:$A,$J8)) | B8: =IF($J8="","",INDEX('Document Register'!$B:$B,$J8)) | C8: =IF($J8="","",INDEX('Document Register'!$C:$C,$J8)) | D8: =IF($J8="","",INDEX('Document Register'!$D:$D,$J8)) | E8: =IF($J8="","",INDEX('Document Register'!$E:$E,$J8)) | F8: =IF($J8="","",INDEX('Document Register'!$F:$F,$J8)) | G8: =IF($J8="","",INDEX('Document Register'!$I:$I,$J8)) | H8: =IF($J8="","",INDEX('Document Register'!$M:$M,$J8)) | J8: =IFERROR(SMALL('Document Register'!$O$5:$O$2000,ROW()-6),"")
A9: =IF($J9="","",INDEX('Document Register'!$A:$A,$J9)) | B9: =IF($J9="","",INDEX('Document Register'!$B:$B,$J9)) | C9: =IF($J9="","",INDEX('Document Register'!$C:$C,$J9)) | D9: =IF($J9="","",INDEX('Document Register'!$D:$D,$J9)) | E9: =IF($J9="","",INDEX('Document Register'!$E:$E,$J9)) | F9: =IF($J9="","",INDEX('Document Register'!$F:$F,$J9)) | G9: =IF($J9="","",INDEX('Document Register'!$I:$I,$J9)) | H9: =IF($J9="","",INDEX('Document Register'!$M:$M,$J9)) | J9: =IFERROR(SMALL('Document Register'!$O$5:$O$2000,ROW()-6),"")
A10: =IF($J10="","",INDEX('Document Register'!$A:$A,$J10)) | B10: =IF($J10="","",INDEX('Document Register'!$B:$B,$J10)) | C10: =IF($J10="","",INDEX('Document Register'!$C:$C,$J10)) | D10: =IF($J10="","",INDEX('Document Register'!$D:$D,$J10)) | E10: =IF($J10="","",INDEX('Document Register'!$E:$E,$J10)) | F10: =IF($J10="","",INDEX('Document Register'!$F:$F,$J10)) | G10: =IF($J10="","",INDEX('Document Register'!$I:$I,$J10)) | H10: =IF($J10="","",INDEX('Document Register'!$M:$M,$J10)) | J10: =IFERROR(SMALL('Document Register'!$O$5:$O$2000,ROW()-6),"")
A11: =IF($J11="","",INDEX('Document Register'!$A:$A,$J11)) | B11: =IF($J11="","",INDEX('Document Register'!$B:$B,$J11)) | C11: =IF($J11="","",INDEX('Document Register'!$C:$C,$J11)) | D11: =IF($J11="","",INDEX('Document Register'!$D:$D,$J11)) | E11: =IF($J11="","",INDEX('Document Register'!$E:$E,$J11)) | F11: =IF($J11="","",INDEX('Document Register'!$F:$F,$J11)) | G11: =IF($J11="","",INDEX('Document Register'!$I:$I,$J11)) | H11: =IF($J11="","",INDEX('Document Register'!$M:$M,$J11)) | J11: =IFERROR(SMALL('Document Register'!$O$5:$O$2000,ROW()-6),"")
A12: =IF($J12="","",INDEX('Document Register'!$A:$A,$J12)) | B12: =IF($J12="","",INDEX('Document Register'!$B:$B,$J12)) | C12: =IF($J12="","",INDEX('Document Register'!$C:$C,$J12)) | D12: =IF($J12="","",INDEX('Document Register'!$D:$D,$J12)) | E12: =IF($J12="","",INDEX('Document Register'!$E:$E,$J12)) | F12: =IF($J12="","",INDEX('Document Register'!$F:$F,$J12)) | G12: =IF($J12="","",INDEX('Document Register'!$I:$I,$J12)) | H12: =IF($J12="","",INDEX('Document Register'!$M:$M,$J12)) | J12: =IFERROR(SMALL('Document Register'!$O$5:$O$2000,ROW()-6),"")
A13: =IF($J13="","",INDEX('Document Register'!$A:$A,$J13)) | B13: =IF($J13="","",INDEX('Document Register'!$B:$B,$J13)) | C13: =IF($J13="","",INDEX('Document Register'!$C:$C,$J13)) | D13: =IF($J13="","",INDEX('Document Register'!$D:$D,$J13)) | E13: =IF($J13="","",INDEX('Document Register'!$E:$E,$J13)) | F13: =IF($J13="","",INDEX('Document Register'!$F:$F,$J13)) | G13: =IF($J13="","",INDEX('Document Register'!$I:$I,$J13)) | H13: =IF($J13="","",INDEX('Document Register'!$M:$M,$J13)) | J13: =IFERROR(SMALL('Document Register'!$O$5:$O$2000,ROW()-6),"")
A14: =IF($J14="","",INDEX('Document Register'!$A:$A,$J14)) | B14: =IF($J14="","",INDEX('Document Register'!$B:$B,$J14)) | C14: =IF($J14="","",INDEX('Document Register'!$C:$C,$J14)) | D14: =IF($J14="","",INDEX('Document Register'!$D:$D,$J14)) | E14: =IF($J14="","",INDEX('Document Register'!$E:$E,$J14)) | F14: =IF($J14="","",INDEX('Document Register'!$F:$F,$J14)) | G14: =IF($J14="","",INDEX('Document Register'!$I:$I,$J14)) | H14: =IF($J14="","",INDEX('Document Register'!$M:$M,$J14)) | J14: =IFERROR(SMALL('Document Register'!$O$5:$O$2000,ROW()-6),"")
A15: =IF($J15="","",INDEX('Document Register'!$A:$A,$J15)) | B15: =IF($J15="","",INDEX('Document Register'!$B:$B,$J15)) | C15: =IF($J15="","",INDEX('Document Register'!$C:$C,$J15)) | D15: =IF($J15="","",INDEX('Document Register'!$D:$D,$J15)) | E15: =IF($J15="","",INDEX('Document Register'!$E:$E,$J15)) | F15: =IF($J15="","",INDEX('Document Register'!$F:$F,$J15)) | G15: =IF($J15="","",INDEX('Document Register'!$I:$I,$J15)) | H15: =IF($J15="","",INDEX('Document Register'!$M:$M,$J15)) | J15: =IFERROR(SMALL('Document Register'!$O$5:$O$2000,ROW()-6),"")
A16: =IF($J16="","",INDEX('Document Register'!$A:$A,$J16)) | B16: =IF($J16="","",INDEX('Document Register'!$B:$B,$J16)) | C16: =IF($J16="","",INDEX('Document Register'!$C:$C,$J16)) | D16: =IF($J16="","",INDEX('Document Register'!$D:$D,$J16)) | E16: =IF($J16="","",INDEX('Document Register'!$E:$E,$J16)) | F16: =IF($J16="","",INDEX('Document Register'!$F:$F,$J16)) | G16: =IF($J16="","",INDEX('Document Register'!$I:$I,$J16)) | H16: =IF($J16="","",INDEX('Document Register'!$M:$M,$J16)) | J16: =IFERROR(SMALL('Document Register'!$O$5:$O$2000,ROW()-6),"")
A17: =IF($J17="","",INDEX('Document Register'!$A:$A,$J17)) | B17: =IF($J17="","",INDEX('Document Register'!$B:$B,$J17)) | C17: =IF($J17="","",INDEX('Document Register'!$C:$C,$J17)) | D17: =IF($J17="","",INDEX('Document Register'!$D:$D,$J17)) | E17: =IF($J17="","",INDEX('Document Register'!$E:$E,$J17)) | F17: =IF($J17="","",INDEX('Document Register'!$F:$F,$J17)) | G17: =IF($J17="","",INDEX('Document Register'!$I:$I,$J17)) | H17: =IF($J17="","",INDEX('Document Register'!$M:$M,$J17)) | J17: =IFERROR(SMALL('Document Register'!$O$5:$O$2000,ROW()-6),"")
A18: =IF($J18="","",INDEX('Document Register'!$A:$A,$J18)) | B18: =IF($J18="","",INDEX('Document Register'!$B:$B,$J18)) | C18: =IF($J18="","",INDEX('Document Register'!$C:$C,$J18)) | D18: =IF($J18="","",INDEX('Document Register'!$D:$D,$J18)) | E18: =IF($J18="","",INDEX('Document Register'!$E:$E,$J18)) | F18: =IF($J18="","",INDEX('Document Register'!$F:$F,$J18)) | G18: =IF($J18="","",INDEX('Document Register'!$I:$I,$J18)) | H18: =IF($J18="","",INDEX('Document Register'!$M:$M,$J18)) | J18: =IFERROR(SMALL('Document Register'!$O$5:$O$2000,ROW()-6),"")
... A56: =IF($J56="","",INDEX('Document Register'!$A:$A,$J56)) | B56: =IF($J56="","",INDEX('Document Register'!$B:$B,$J56)) | C56: =IF($J56="","",INDEX('Document Register'!$C:$C,$J56)) | D56: =IF($J56="","",INDEX('Document Register'!$D:$D,$J56)) | E56: =IF($J56="","",INDEX('Document Register'!$E:$E,$J56)) | F56: =IF($J56="","",INDEX('Document Register'!$F:$F,$J56)) | G56: =IF($J56="","",INDEX('Document Register'!$I:$I,$J56)) | H56: =IF($J56="","",INDEX('Document Register'!$M:$M,$J56)) | J56: =IFERROR(SMALL('Document Register'!$O$5:$O$2000,ROW()-6),"")

Sheet Document Register
A1: Document Control Register
A2: Coastal Tunnel Package (CTP) – Desert Horizon JV • Client: Coastal Gateway Development Authority • Demo data
A4: Document No. | B4: Title | C4: Type | D4: Discipline | E4: Rev | F4: Submitted | G4: Transmittal No. | H4: Reviewer | I4: Review Status | J4: Response | K4: Days in Review | L4: Next Action | M4: File Location
A5: CTP-DHJ-HSE-MAT-0003 | B5: Ventilation fans | C5: Material Submittal | D5: HSE | E5: A | F5: 46083 | G5: TRN-01059 | H5: Meridian Engineering Partners | I5: Code B – Approved with Comments | J5: 46089 | K5: =IF(J5="",TODAY()-F5,J5-F5) | L5: Incorporate comments | M5: \\DC\HSE\Material Submittal\CTP-DHJ-HSE-MAT-0003 | O5: =IF(Search!$C$4="","",IF(ISNUMBER(SEARCH(Search!$C$4,A5&" "&B5&" "&C5&" "&D5&" "&G5&" "&I5)),ROW(),""))
A6: CTP-DHJ-HSE-MAT-0001 | B6: Precast segment gaskets | C6: Material Submittal | D6: HSE | E6: A | F6: 46085 | G6: TRN-01003 | H6: Meridian Engineering Partners | I6: Code C – Revise & Resubmit | J6: 46091 | K6: =IF(J6="",TODAY()-F6,J6-F6) | L6: Revise and resubmit | M6: \\DC\HSE\Material Submittal\CTP-DHJ-HSE-MAT-0001 | O6: =IF(Search!$C$4="","",IF(ISNUMBER(SEARCH(Search!$C$4,A6&" "&B6&" "&C6&" "&D6&" "&G6&" "&I6)),ROW(),""))
A7: CTP-DHJ-MEP-MAT-0003 | B7: Ventilation fans | C7: Material Submittal | D7: MEP | E7: A | F7: 46087 | G7: TRN-01034 | H7: Meridian Engineering Partners | I7: Code A – Approved | J7: 46107 | K7: =IF(J7="",TODAY()-F7,J7-F7) | L7: Issue for construction | M7: \\DC\MEP\Material Submittal\CTP-DHJ-MEP-MAT-0003 | O7: =IF(Search!$C$4="","",IF(ISNUMBER(SEARCH(Search!$C$4,A7&" "&B7&" "&C7&" "&D7&" "&G7&" "&I7)),ROW(),""))
A8: CTP-DHJ-HSE-RPT-0004 | B8: Weld inspection | C8: Inspection Report | D8: HSE | E8: A | F8: 46087 | G8: TRN-01086 | H8: Meridian Engineering Partners | I8: Code A – Approved | J8: 46099 | K8: =IF(J8="",TODAY()-F8,J8-F8) | L8: Issue for construction | M8: \\DC\HSE\Inspection Report\CTP-DHJ-HSE-RPT-0004 | O8: =IF(Search!$C$4="","",IF(ISNUMBER(SEARCH(Search!$C$4,A8&" "&B8&" "&C8&" "&D8&" "&G8&" "&I8)),ROW(),""))
A9: CTP-DHJ-TUN-MAT-0011 | B9: Precast segment gaskets | C9: Material Submittal | D9: Tunnelling | E9: 1 | F9: 46087 | G9: TRN-01215 | H9: Meridian Engineering Partners | I9: Code D – Rejected | J9: 46106 | K9: =IF(J9="",TODAY()-F9,J9-F9) | L9: Prepare new submission | M9: \\DC\Tunnelling\Material Submittal\CTP-DHJ-TUN-MAT-0011 | O9: =IF(Search!$C$4="","",IF(ISNUMBER(SEARCH(Search!$C$4,A9&" "&B9&" "&C9&" "&D9&" "&G9&" "&I9)),ROW(),""))
A10: CTP-DHJ-GEO-DWG-0010 | B10: Drainage layout | C10: Drawing | D10: Geotechnical | E10: A | F10: 46088 | G10: TRN-01178 | H10: Meridian Engineering Partners | I10: Code A – Approved | J10: 46107 | K10: =IF(J10="",TODAY()-F10,J10-F10) | L10: Issue for construction | M10: \\DC\Geotechnical\Drawing\CTP-DHJ-GEO-DWG-0010 | O10: =IF(Search!$C$4="","",IF(ISNUMBER(SEARCH(Search!$C$4,A10&" "&B10&" "&C10&" "&D10&" "&G10&" "&I10)),ROW(),""))
A11: CTP-DHJ-GEO-MAT-0008 | B11: Precast segment gaskets | C11: Material Submittal | D11: Geotechnical | E11: B | F11: 46089 | G11: TRN-01231 | H11: Meridian Engineering Partners | I11: Code B – Approved with Comments | J11: 46096 | K11: =IF(J11="",TODAY()-F11,J11-F11) | L11: Incorporate comments | M11: \\DC\Geotechnical\Material Submittal\CTP-DHJ-GEO-MAT-0008 | O11: =IF(Search!$C$4="","",IF(ISNUMBER(SEARCH(Search!$C$4,A11&" "&B11&" "&C11&" "&D11&" "&G11&" "&I11)),ROW(),""))
A12: CTP-DHJ-MEP-DWG-0011 | B12: Portal structure details | C12: Drawing | D12: MEP | E12: 1 | F12: 46090 | G12: TRN-01165 | H12: Meridian Engineering Partners | I12: Code A – Approved | J12: 46098 | K12: =IF(J12="",TODAY()-F12,J12-F12) | L12: Issue for construction | M12: \\DC\MEP\Drawing\CTP-DHJ-MEP-DWG-0011 | O12: =IF(Search!$C$4="","",IF(ISNUMBER(SEARCH(Search!$C$4,A12&" "&B12&" "&C12&" "&D12&" "&G12&" "&I12)),ROW(),""))
A13: CTP-DHJ-TUN-MST-0002 | B13: Waterproofing installation | C13: Method Statement | D13: Tunnelling | E13: 1 | F13: 46091 | G13: TRN-01053 | H13: Meridian Engineering Partners | I13: Code A – Approved | J13: 46104 | K13: =IF(J13="",TODAY()-F13,J13-F13) | L13: Issue for construction | M13: \\DC\Tunnelling\Method Statement\CTP-DHJ-TUN-MST-0002 | O13: =IF(Search!$C$4="","",IF(ISNUMBER(SEARCH(Search!$C$4,A13&" "&B13&" "&C13&" "&D13&" "&G13&" "&I13)),ROW(),""))
A14: CTP-DHJ-MEP-MAT-0010 | B14: Grout admixture | C14: Material Submittal | D14: MEP | E14: B | F14: 46092 | G14: TRN-01217 | H14: Meridian Engineering Partners | I14: Code A – Approved | J14: 46098 | K14: =IF(J14="",TODAY()-F14,J14-F14) | L14: Issue for construction | M14: \\DC\MEP\Material Submittal\CTP-DHJ-MEP-MAT-0010 | O14: =IF(Search!$C$4="","",IF(ISNUMBER(SEARCH(Search!$C$4,A14&" "&B14&" "&C14&" "&D14&" "&G14&" "&I14)),ROW(),""))
A15: CTP-DHJ-HSE-MST-0007 | B15: TBM launching | C15: Method Statement | D15: HSE | E15: 1 | F15: 46094 | G15: TRN-01087 | H15: Meridian Engineering Partners | I15: Code B – Approved with Comments | J15: 46099 | K15: =IF(J15="",TODAY()-F15,J15-F15) | L15: Incorporate comments | M15: \\DC\HSE\Method Statement\CTP-DHJ-HSE-MST-0007 | O15: =IF(Search!$C$4="","",IF(ISNUMBER(SEARCH(Search!$C$4,A15&" "&B15&" "&C15&" "&D15&" "&G15&" "&I15)),ROW(),""))
A16: CTP-DHJ-QAQ-MST-0005 | B16: Waterproofing installation | C16: Method Statement | D16: Quality | E16: B | F16: 46096 | G16: TRN-01208 | H16: Meridian Engineering Partners | I16: Code B – Approved with Comments | J16: 46115 | K16: =IF(J16="",TODAY()-F16,J16-F16) | L16: Incorporate comments | M16: \\DC\Quality\Method Statement\CTP-DHJ-QAQ-MST-0005 | O16: =IF(Search!$C$4="","",IF(ISNUMBER(SEARCH(Search!$C$4,A16&" "&B16&" "&C16&" "&D16&" "&G16&" "&I16)),ROW(),""))
... A206: CTP-DHJ-HSE-MAT-0007 | B206: Ventilation fans | C206: Material Submittal | D206: HSE | E206: 0 | F206: 46273 | G206: TRN-01146 | H206: Meridian Engineering Partners | I206: Code A – Approved | J206: 46290 | K206: =IF(J206="",TODAY()-F206,J206-F206) | L206: Issue for construction | M206: \\DC\HSE\Material Submittal\CTP-DHJ-HSE-MAT-0007 | O206: =IF(Search!$C$4="","",IF(ISNUMBER(SEARCH(Search!$C$4,A206&" "&B206&" "&C206&" "&D206&" "&G206&" "&I206)),ROW(),""))
A207: CTP-DHJ-TUN-MAT-0005 | B207: Ventilation fans | C207: Material Submittal | D207: Tunnelling | E207: B | F207: 46275 | G207: TRN-01105 | H207: Meridian Engineering Partners | I207: Under Review | K207: =IF(J207="",TODAY()-F207,J207-F207) | L207: Follow up with consultant | M207: \\DC\Tunnelling\Material Submittal\CTP-DHJ-TUN-MAT-0005 | O207: =IF(Search!$C$4="","",IF(ISNUMBER(SEARCH(Search!$C$4,A207&" "&B207&" "&C207&" "&D207&" "&G207&" "&I207)),ROW(),""))
A208: CTP-DHJ-TUN-CAL-0003 | B208: Lifting plan | C208: Calculation | D208: Tunnelling | E208: 0 | F208: 46276 | G208: TRN-01056 | H208: Meridian Engineering Partners | I208: Code A – Approved | J208: 46286 | K208: =IF(J208="",TODAY()-F208,J208-F208) | L208: Issue for construction | M208: \\DC\Tunnelling\Calculation\CTP-DHJ-TUN-CAL-0003 | O208: =IF(Search!$C$4="","",IF(ISNUMBER(SEARCH(Search!$C$4,A208&" "&B208&" "&C208&" "&D208&" "&G208&" "&I208)),ROW(),""))
A209: CTP-DHJ-QAQ-MAT-0001 | B209: Fire-rated cables | C209: Material Submittal | D209: Quality | E209: B | F209: 46276 | G209: TRN-01073 | H209: Meridian Engineering Partners | I209: Code D – Rejected | J209: 46283 | K209: =IF(J209="",TODAY()-F209,J209-F209) | L209: Prepare new submission | M209: \\DC\Quality\Material Submittal\CTP-DHJ-QAQ-MAT-0001 | O209: =IF(Search!$C$4="","",IF(ISNUMBER(SEARCH(Search!$C$4,A209&" "&B209&" "&C209&" "&D209&" "&G209&" "&I209)),ROW(),""))
A210: CTP-DHJ-HSE-DWG-0009 | B210: Portal structure details | C210: Drawing | D210: HSE | E210: B | F210: 46276 | G210: TRN-01109 | H210: Meridian Engineering Partners | I210: Code C – Revise & Resubmit | J210: 46292 | K210: =IF(J210="",TODAY()-F210,J210-F210) | L210: Revise and resubmit | M210: \\DC\HSE\Drawing\CTP-DHJ-HSE-DWG-0009 | O210: =IF(Search!$C$4="","",IF(ISNUMBER(SEARCH(Search!$C$4,A210&" "&B210&" "&C210&" "&D210&" "&G210&" "&I210)),ROW(),""))
A211: CTP-DHJ-TUN-DWG-0004 | B211: Cross passage reinforcement | C211: Drawing | D211: Tunnelling | E211: 1 | F211: 46277 | G211: TRN-01074 | H211: Meridian Engineering Partners | I211: Code A – Approved | J211: 46286 | K211: =IF(J211="",TODAY()-F211,J211-F211) | L211: Issue for construction | M211: \\DC\Tunnelling\Drawing\CTP-DHJ-TUN-DWG-0004 | O211: =IF(Search!$C$4="","",IF(ISNUMBER(SEARCH(Search!$C$4,A211&" "&B211&" "&C211&" "&D211&" "&G211&" "&I211)),ROW(),""))
A212: CTP-DHJ-QAQ-DWG-0001 | B212: Drainage layout | C212: Drawing | D212: Quality | E212: A | F212: 46278 | G212: TRN-01013 | H212: Meridian Engineering Partners | I212: Code B – Approved with Comments | J212: 46295 | K212: =IF(J212="",TODAY()-F212,J212-F212) | L212: Incorporate comments | M212: \\DC\Quality\Drawing\CTP-DHJ-QAQ-DWG-0001 | O212: =IF(Search!$C$4="","",IF(ISNUMBER(SEARCH(Search!$C$4,A212&" "&B212&" "&C212&" "&D212&" "&G212&" "&I212)),ROW(),""))
A213: CTP-DHJ-TUN-MST-0001 | B213: TBM launching | C213: Method Statement | D213: Tunnelling | E213: B | F213: 46279 | G213: TRN-01016 | H213: Meridian Engineering Partners | I213: Code C – Revise & Resubmit | J213: 46286 | K213: =IF(J213="",TODAY()-F213,J213-F213) | L213: Revise and resubmit | M213: \\DC\Tunnelling\Method Statement\CTP-DHJ-TUN-MST-0001 | O213: =IF(Search!$C$4="","",IF(ISNUMBER(SEARCH(Search!$C$4,A213&" "&B213&" "&C213&" "&D213&" "&G213&" "&I213)),ROW(),""))
A214: CTP-DHJ-CIV-MAT-0002 | B214: Precast segment gaskets | C214: Material Submittal | D214: Civil | E214: 0 | F214: 46281 | G214: TRN-01010 | H214: Meridian Engineering Partners | I214: Code A – Approved | J214: 46296 | K214: =IF(J214="",TODAY()-F214,J214-F214) | L214: Issue for construction | M214: \\DC\Civil\Material Submittal\CTP-DHJ-CIV-MAT-0002 | O214: =IF(Search!$C$4="","",IF(ISNUMBER(SEARCH(Search!$C$4,A214&" "&B214&" "&C214&" "&D214&" "&G214&" "&I214)),ROW(),""))
A215: CTP-DHJ-QAQ-MST-0001 | B215: Annulus grouting | C215: Method Statement | D215: Quality | E215: 1 | F215: 46284 | G215: TRN-01043 | H215: Meridian Engineering Partners | I215: Code B – Approved with Comments | J215: 46303 | K215: =IF(J215="",TODAY()-F215,J215-F215) | L215: Incorporate comments | M215: \\DC\Quality\Method Statement\CTP-DHJ-QAQ-MST-0001 | O215: =IF(Search!$C$4="","",IF(ISNUMBER(SEARCH(Search!$C$4,A215&" "&B215&" "&C215&" "&D215&" "&G215&" "&I215)),ROW(),""))
A216: CTP-DHJ-HSE-MST-0002 | B216: Cable pulling | C216: Method Statement | D216: HSE | E216: B | F216: 46285 | G216: TRN-01001 | H216: Meridian Engineering Partners | I216: Code A – Approved | J216: 46292 | K216: =IF(J216="",TODAY()-F216,J216-F216) | L216: Issue for construction | M216: \\DC\HSE\Method Statement\CTP-DHJ-HSE-MST-0002 | O216: =IF(Search!$C$4="","",IF(ISNUMBER(SEARCH(Search!$C$4,A216&" "&B216&" "&C216&" "&D216&" "&G216&" "&I216)),ROW(),""))
A217: CTP-DHJ-CIV-MST-0008 | B217: Annulus grouting | C217: Method Statement | D217: Civil | E217: B | F217: 46285 | G217: TRN-01210 | H217: Meridian Engineering Partners | I217: Code A – Approved | J217: 46302 | K217: =IF(J217="",TODAY()-F217,J217-F217) | L217: Issue for construction | M217: \\DC\Civil\Method Statement\CTP-DHJ-CIV-MST-0008 | O217: =IF(Search!$C$4="","",IF(ISNUMBER(SEARCH(Search!$C$4,A217&" "&B217&" "&C217&" "&D217&" "&G217&" "&I217)),ROW(),""))
A218: CTP-DHJ-QAQ-RPT-0002 | B218: Concrete cube results | C218: Inspection Report | D218: Quality | E218: A | F218: 46285 | G218: TRN-01237 | H218: Meridian Engineering Partners | I218: Code A – Approved | J218: 46300 | K218: =IF(J218="",TODAY()-F218,J218-F218) | L218: Issue for construction | M218: \\DC\Quality\Inspection Report\CTP-DHJ-QAQ-RPT-0002 | O218: =IF(Search!$C$4="","",IF(ISNUMBER(SEARCH(Search!$C$4,A218&" "&B218&" "&C218&" "&D218&" "&G218&" "&I218)),ROW(),""))
A219: CTP-DHJ-TUN-MAT-0003 | B219: Ventilation fans | C219: Material Submittal | D219: Tunnelling | E219: A | F219: 46286 | G219: TRN-01083 | H219: Meridian Engineering Partners | I219: Code A – Approved | J219: 46302 | K219: =IF(J219="",TODAY()-F219,J219-F219) | L219: Issue for construction | M219: \\DC\Tunnelling\Material Submittal\CTP-DHJ-TUN-MAT-0003 | O219: =IF(Search!$C$4="","",IF(ISNUMBER(SEARCH(Search!$C$4,A219&" "&B219&" "&C219&" "&D219&" "&G219&" "&I219)),ROW(),""))
A220: CTP-DHJ-MEP-DWG-0007 | B220: Cross passage reinforcement | C220: Drawing | D220: MEP | E220: A | F220: 46286 | G220: TRN-01129 | H220: Meridian Engineering Partners | I220: Under Review | K220: =IF(J220="",TODAY()-F220,J220-F220) | L220: Follow up with consultant | M220: \\DC\MEP\Drawing\CTP-DHJ-MEP-DWG-0007 | O220: =IF(Search!$C$4="","",IF(ISNUMBER(SEARCH(Search!$C$4,A220&" "&B220&" "&C220&" "&D220&" "&G220&" "&I220)),ROW(),""))
A221: CTP-DHJ-HSE-PRC-0001 | B221: Document control procedure | C221: Procedure | D221: HSE | E221: A | F221: 46287 | G221: TRN-01060 | H221: Meridian Engineering Partners | I221: Code A – Approved | J221: 46297 | K221: =IF(J221="",TODAY()-F221,J221-F221) | L221: Issue for construction | M221: \\DC\HSE\Procedure\CTP-DHJ-HSE-PRC-0001 | O221: =IF(Search!$C$4="","",IF(ISNUMBER(SEARCH(Search!$C$4,A221&" "&B221&" "&C221&" "&D221&" "&G221&" "&I221)),ROW(),""))
A222: CTP-DHJ-TUN-MST-0003 | B222: Annulus grouting | C222: Method Statement | D222: Tunnelling | E222: 1 | F222: 46287 | G222: TRN-01125 | H222: Meridian Engineering Partners | I222: Under Review | K222: =IF(J222="",TODAY()-F222,J222-F222) | L222: Follow up with consultant | M222: \\DC\Tunnelling\Method Statement\CTP-DHJ-TUN-MST-0003 | O222: =IF(Search!$C$4="","",IF(ISNUMBER(SEARCH(Search!$C$4,A222&" "&B222&" "&C222&" "&D222&" "&G222&" "&I222)),ROW(),""))
A223: CTP-DHJ-GEO-RPT-0003 | B223: Concrete cube results | C223: Inspection Report | D223: Geotechnical | E223: A | F223: 46287 | G223: TRN-01186 | H223: Meridian Engineering Partners | I223: Code C – Revise & Resubmit | J223: 46301 | K223: =IF(J223="",TODAY()-F223,J223-F223) | L223: Revise and resubmit | M223: \\DC\Geotechnical\Inspection Report\CTP-DHJ-GEO-RPT-0003 | O223: =IF(Search!$C$4="","",IF(ISNUMBER(SEARCH(Search!$C$4,A223&" "&B223&" "&C223&" "&D223&" "&G223&" "&I223)),ROW(),""))
A224: CTP-DHJ-MEP-RPT-0006 | B224: Air quality monitoring | C224: Inspection Report | D224: MEP | E224: 0 | F224: 46287 | G224: TRN-01227 | H224: Meridian Engineering Partners | I224: Code B – Approved with Comments | J224: 46292 | K224: =IF(J224="",TODAY()-F224,J224-F224) | L224: Incorporate comments | M224: \\DC\MEP\Inspection Report\CTP-DHJ-MEP-RPT-0006 | O224: =IF(Search!$C$4="","",IF(ISNUMBER(SEARCH(Search!$C$4,A224&" "&B224&" "&C224&" "&D224&" "&G224&" "&I224)),ROW(),""))
A225: CTP-DHJ-MEP-MAT-0013 | B225: Ventilation fans | C225: Material Submittal | D225: MEP | E225: 0 | F225: 46288 | G225: TRN-01239 | H225: Meridian Engineering Partners | I225: Code A – Approved | J225: 46304 | K225: =IF(J225="",TODAY()-F225,J225-F225) | L225: Issue for construction | M225: \\DC\MEP\Material Submittal\CTP-DHJ-MEP-MAT-0013 | O225: =IF(Search!$C$4="","",IF(ISNUMBER(SEARCH(Search!$C$4,A225&" "&B225&" "&C225&" "&D225&" "&G225&" "&I225)),ROW(),""))
A226: CTP-DHJ-CIV-PRC-0002 | B226: Material receiving | C226: Procedure | D226: Civil | E226: A | F226: 46289 | G226: TRN-01054 | H226: Meridian Engineering Partners | I226: Code A – Approved | J226: 46299 | K226: =IF(J226="",TODAY()-F226,J226-F226) | L226: Issue for construction | M226: \\DC\Civil\Procedure\CTP-DHJ-CIV-PRC-0002 | O226: =IF(Search!$C$4="","",IF(ISNUMBER(SEARCH(Search!$C$4,A226&" "&B226&" "&C226&" "&D226&" "&G226&" "&I226)),ROW(),""))
A227: CTP-DHJ-TUN-MAT-0008 | B227: Grout admixture | C227: Material Submittal | D227: Tunnelling | E227: 0 | F227: 46293 | G227: TRN-01162 | H227: Meridian Engineering Partners | I227: Under Review | K227: =IF(J227="",TODAY()-F227,J227-F227) | L227: Follow up with consultant | M227: \\DC\Tunnelling\Material Submittal\CTP-DHJ-TUN-MAT-0008 | O227: =IF(Search!$C$4="","",IF(ISNUMBER(SEARCH(Search!$C$4,A227&" "&B227&" "&C227&" "&D227&" "&G227&" "&I227)),ROW(),""))
A228: CTP-DHJ-GEO-RPT-0002 | B228: Monthly settlement monitoring | C228: Inspection Report | D228: Geotechnical | E228: A | F228: 46294 | G228: TRN-01163 | H228: Meridian Engineering Partners | I228: Code B – Approved with Comments | J228: 46309 | K228: =IF(J228="",TODAY()-F228,J228-F228) | L228: Incorporate comments | M228: \\DC\Geotechnical\Inspection Report\CTP-DHJ-GEO-RPT-0002 | O228: =IF(Search!$C$4="","",IF(ISNUMBER(SEARCH(Search!$C$4,A228&" "&B228&" "&C228&" "&D228&" "&G228&" "&I228)),ROW(),""))
A229: CTP-DHJ-MEP-MST-0003 | B229: Waterproofing installation | C229: Method Statement | D229: MEP | E229: B | F229: 46295 | G229: TRN-01071 | H229: Meridian Engineering Partners | I229: Code D – Rejected | J229: 46306 | K229: =IF(J229="",TODAY()-F229,J229-F229) | L229: Prepare new submission | M229: \\DC\MEP\Method Statement\CTP-DHJ-MEP-MST-0003 | O229: =IF(Search!$C$4="","",IF(ISNUMBER(SEARCH(Search!$C$4,A229&" "&B229&" "&C229&" "&D229&" "&G229&" "&I229)),ROW(),""))
A230: CTP-DHJ-MEP-RPT-0002 | B230: Survey control check | C230: Inspection Report | D230: MEP | E230: 1 | F230: 46295 | G230: TRN-01124 | H230: Meridian Engineering Partners | I230: Code A – Approved | J230: 46300 | K230: =IF(J230="",TODAY()-F230,J230-F230) | L230: Issue for construction | M230: \\DC\MEP\Inspection Report\CTP-DHJ-MEP-RPT-0002 | O230: =IF(Search!$C$4="","",IF(ISNUMBER(SEARCH(Search!$C$4,A230&" "&B230&" "&C230&" "&D230&" "&G230&" "&I230)),ROW(),""))
...
