Workbook

Sheet Executive Dashboard
B1: PROCUREMENT & PAYMENT CONTROL CENTER
B3: Executive Procurement Visibility | PR → PO → Delivery → Invoice → Payment | Aging & Vendor Exposure
B5: =SUM('Procurement Register'!G2:G61) -> 13165000 | D5: =SUM('Procurement Register'!J2:J61) -> 9812903 | F5: =SUM('Procurement Register'!I2:I61) -> 3352097 | H5: =COUNTIF('Procurement Register'!Q2:Q61,">0") -> 26 | K5: =COUNTIF('Procurement Register'!L2:L61,"High") -> 16
B7: Total Commitments | D7: Outstanding Balance | F7: Paid to Date | H7: Overdue Payment Items | K7: High-Priority Items
B9: PROCUREMENT WORKFLOW STATUS
B10: =COUNTIF('Procurement Register'!K2:K61,"PR Raised") -> 3 | D10: =COUNTIF('Procurement Register'!K2:K61,"PR Approved") -> 4 | F10: =COUNTIF('Procurement Register'!K2:K61,"PO Issued") -> 8 | H10: =COUNTIF('Procurement Register'!K2:K61,"Delivered") -> 6 | J10: =COUNTIF('Procurement Register'!K2:K61,"Invoice Received") -> 9 | L10: =COUNTIF('Procurement Register'!K2:K61,"Under Review") -> 8
B12: PR Raised | D12: PR Approved | F12: PO Issued | H12: Delievered | J12: Invoice Received | L12: Under Review
B14: PR Raised • PR Approved • PO Issued • Delivered • Invoice Received • Under Review • Approved for Payment • Paid
B16: OVERDUE ITEMS | G16: MANAGEMENT ATTENTION | K16: TOP VENDOR EXPOSURE
B17: =COUNTIF('Procurement Register'!Q2:Q61,">0") -> 26 | G17: ="Overdue exposure: "&TEXT(SUMIFS('Procurement Register'!J2:J61,'Procurement Register'!Q2:Q61,">0"),"#,##0")&" SAR"&CHAR(10)&"High-priority open items: "&TEXT(COUNTIFS('Procurement Register'!L2:L61,"High",'Procurement Register'!K2:K61,"<>Paid"),"0") -> Overdue exposure: 3,111,170 SAR High-priority open items: 13 | K17: Vendor | L17: Outstanding
K18: Atlas Services | L18: =SUMIF('Procurement Register'!C:C,K18,'Procurement Register'!J:J) -> 1221840
K19: Prime Logistics | L19: =SUMIF('Procurement Register'!C:C,K19,'Procurement Register'!J:J) -> 1375997
B20: HIGH PRIORITY | K20: Gulf Technical | L20: =SUMIF('Procurement Register'!C:C,K20,'Procurement Register'!J:J) -> 1628709
B21: =COUNTIF('Procurement Register'!L2:L61,"High") -> 16 | K21: Horizon Supply | L21: =SUMIF('Procurement Register'!C:C,K21,'Procurement Register'!J:J) -> 601988
K22: Vertex Trading | L22: =SUMIF('Procurement Register'!C:C,K22,'Procurement Register'!J:J) -> 1624007
G23: AGING PROFILE | K23: Nexa Facilities | L23: =SUMIF('Procurement Register'!C:C,K23,'Procurement Register'!J:J) -> 1792757
G24: Aging Band | H24: Items | K24: Summit Industrial | L24: =SUMIF('Procurement Register'!C:C,K24,'Procurement Register'!J:J) -> 886605
G25: 0 Days | H25: =COUNTIF('Procurement Register'!Q2:Q61,0) -> 34 | K25: BlueLine Services | L25: =SUMIF('Procurement Register'!C:C,K25,'Procurement Register'!J:J) -> 681000
G26: 1-30 Days | H26: =COUNTIFS('Procurement Register'!Q2:Q61,">=1",'Procurement Register'!Q2:Q61,"<=30") -> 6
G27: 31-60 Days | H27: =COUNTIFS('Procurement Register'!Q2:Q61,">=31",'Procurement Register'!Q2:Q61,"<=60") -> 7
G28: 60+ Days | H28: =COUNTIF('Procurement Register'!Q2:Q61,">60") -> 13 | K28: Department | L28: Outstanding
K29: Operations | L29: =SUMIF('Procurement Register'!B:B,K29,'Procurement Register'!J:J) -> 898403
K30: Administration | L30: =SUMIF('Procurement Register'!B:B,K30,'Procurement Register'!J:J) -> 218991
K31: Logistics | L31: =SUMIF('Procurement Register'!B:B,K31,'Procurement Register'!J:J) -> 1332066
K32: Procurement | L32: =SUMIF('Procurement Register'!B:B,K32,'Procurement Register'!J:J) -> 1026822
K33: Document Control | L33: =SUMIF('Procurement Register'!B:B,K33,'Procurement Register'!J:J) -> 1574502
K34: Finance | L34: =SUMIF('Procurement Register'!B:B,K34,'Procurement Register'!J:J) -> 2069950
K35: Executive Office | L35: =SUMIF('Procurement Register'!B:B,K35,'Procurement Register'!J:J) -> 1200738
K36: Facilities | L36: =SUMIF('Procurement Register'!B:B,K36,'Procurement Register'!J:J) -> 1491431
B37: Portfolio note Synthetic / anonymized procurement data. No confidential company or vendor information is included.

Sheet Procurement Register
A1: Ref No. | B1: Department | C1: Vendor | D1: PR No. | E1: PO No. | F1: Description | G1: Commitment (SAR) | H1: Invoice Value (SAR) | I1: Paid (SAR) | J1: Outstanding (SAR) | K1: Status | L1: Priority | M1: PR Date | N1: PO Date | O1: Invoice Date | P1: Due Date | Q1: Days Aging | R1: Owner | S1: Management Note
A2: PCR-001 | B2: Facilities | C2: Vertex Trading | D2: PR-2601 | E2: PO-8101 | F2: IT equipment | G2: 91000 | H2: 76932 | I2: 57569 | J2: =G2-I2 -> 33431 | K2: Approved for Payment | L2: Medium | M2: 46092 | N2: 46103 | O2: 46139 | P2: 46169 | Q2: =IF(AND(P2<>"",J2>0),MAX(TODAY()-P2,0),0) -> 61 | R2: M. Ali | S2: Escalate overdue item
A3: PCR-002 | B3: Operations | C3: Gulf Technical | D3: PR-2602 | E3: PO-8102 | F3: Professional services | G3: 191000 | H3: 186510 | I3: 186510 | J3: =G3-I3 -> 4490 | K3: Paid | L3: Medium | M3: 46200 | N3: 46209 | O3: 46220 | P3: 46250 | Q3: =IF(AND(P3<>"",J3>0),MAX(TODAY()-P3,0),0) -> 0 | R3: S. Ahmed | S3: Routine follow-up
A4: PCR-003 | B4: Executive Office | C4: Prime Logistics | D4: PR-2603 | E4: 77 | F4: Transport services | G4: 356000 | H4: 0 | I4: 0 | J4: =G4-I4 -> 356000 | K4: PR Raised | L4: High | M4: 46085 | Q4: =IF(AND(P4<>"",J4>0),MAX(TODAY()-P4,0),0) -> 0 | R4: A. Khan | S4: Routine follow-up
A5: PCR-004 | B5: Executive Office | C5: BlueLine Services | D5: PR-2604 | E5: 77 | F5: Technical materials | G5: 87000 | H5: 0 | I5: 0 | J5: =G5-I5 -> 87000 | K5: PR Approved | L5: Medium | M5: 46077 | Q5: =IF(AND(P5<>"",J5>0),MAX(TODAY()-P5,0),0) -> 0 | R5: F. Malik | S5: Routine follow-up
A6: PCR-005 | B6: Logistics | C6: Atlas Services | D6: PR-2605 | E6: PO-8105 | F6: IT equipment | G6: 60000 | H6: 51007 | I6: 0 | J6: =G6-I6 -> 60000 | K6: Under Review | L6: Medium | M6: 46108 | N6: 46126 | O6: 46163 | P6: 46193 | Q6: =IF(AND(P6<>"",J6>0),MAX(TODAY()-P6,0),0) -> 37 | R6: R. Hassan | S6: Escalate overdue item
A7: PCR-006 | B7: Operations | C7: Prime Logistics | D7: PR-2606 | E7: PO-8106 | F7: Manpower services | G7: 357000 | H7: 291094 | I7: 291094 | J7: =G7-I7 -> 65906 | K7: Paid | L7: Low | M7: 46123 | N7: 46138 | O7: 46164 | P7: 46194 | Q7: =IF(AND(P7<>"",J7>0),MAX(TODAY()-P7,0),0) -> 36 | R7: S. Ahmed | S7: Escalate overdue item
A8: PCR-007 | B8: Procurement | C8: Nexa Facilities | D8: PR-2607 | E8: PO-8107 | F8: Equipment rental | G8: 409000 | H8: 0 | I8: 0 | J8: =G8-I8 -> 409000 | K8: Delivered | L8: Medium | M8: 46087 | N8: 46095 | Q8: =IF(AND(P8<>"",J8>0),MAX(TODAY()-P8,0),0) -> 0 | R8: R. Hassan | S8: Routine follow-up
A9: PCR-008 | B9: Executive Office | C9: Atlas Services | D9: PR-2608 | E9: PO-8108 | F9: Transport services | G9: 236000 | H9: 179565 | I9: 0 | J9: =G9-I9 -> 236000 | K9: Invoice Received | L9: High | M9: 46163 | N9: 46169 | O9: 46211 | P9: 46241 | Q9: =IF(AND(P9<>"",J9>0),MAX(TODAY()-P9,0),0) -> 0 | R9: M. Ali | S9: Routine follow-up
A10: PCR-009 | B10: Administration | C10: Vertex Trading | D10: PR-2609 | E10: 77 | F10: Equipment rental | G10: 194000 | H10: 0 | I10: 0 | J10: =G10-I10 -> 194000 | K10: PR Raised | L10: High | M10: 46061 | Q10: =IF(AND(P10<>"",J10>0),MAX(TODAY()-P10,0),0) -> 0 | R10: F. Malik | S10: Routine follow-up
A11: PCR-010 | B11: Facilities | C11: Nexa Facilities | D11: PR-2610 | E11: PO-8110 | F11: Office supplies | G11: 261000 | H11: 0 | I11: 0 | J11: =G11-I11 -> 261000 | K11: PO Issued | L11: High | M11: 46092 | N11: 46102 | Q11: =IF(AND(P11<>"",J11>0),MAX(TODAY()-P11,0),0) -> 0 | R11: R. Hassan | S11: Routine follow-up
A12: PCR-011 | B12: Finance | C12: Gulf Technical | D12: PR-2611 | E12: PO-8111 | F12: Technical materials | G12: 328000 | H12: 0 | I12: 0 | J12: =G12-I12 -> 328000 | K12: PO Issued | L12: Medium | M12: 46214 | N12: 46225 | Q12: =IF(AND(P12<>"",J12>0),MAX(TODAY()-P12,0),0) -> 0 | R12: M. Ali | S12: Routine follow-up
A13: PCR-012 | B13: Procurement | C13: Atlas Services | D13: PR-2612 | E13: PO-8112 | F13: Technical materials | G13: 77000 | H13: 76688 | I13: 0 | J13: =G13-I13 -> 77000 | K13: Invoice Received | L13: High | M13: 46076 | N13: 46083 | O13: 46091 | P13: 46121 | Q13: =IF(AND(P13<>"",J13>0),MAX(TODAY()-P13,0),0) -> 109 | R13: S. Ahmed | S13: Escalate overdue item
A14: PCR-013 | B14: Administration | C14: Horizon Supply | D14: PR-2613 | E14: PO-8113 | F14: Site consumables | G14: 268000 | H14: 243009 | I14: 243009 | J14: =G14-I14 -> 24991 | K14: Paid | L14: Medium | M14: 46148 | N14: 46165 | O14: 46182 | P14: 46212 | Q14: =IF(AND(P14<>"",J14>0),MAX(TODAY()-P14,0),0) -> 18 | R14: S. Ahmed | S14: Routine follow-up
A15: PCR-014 | B15: Operations | C15: Vertex Trading | D15: PR-2614 | E15: PO-8114 | F15: Maintenance works | G15: 345000 | H15: 0 | I15: 0 | J15: =G15-I15 -> 345000 | K15: Delivered | L15: Low | M15: 46102 | N15: 46111 | Q15: =IF(AND(P15<>"",J15>0),MAX(TODAY()-P15,0),0) -> 0 | R15: F. Malik | S15: Routine follow-up
A16: PCR-015 | B16: Document Control | C16: Atlas Services | D16: PR-2615 | E16: PO-8115 | F16: Accommodation services | G16: 85000 | H16: 75607 | I16: 28951 | J16: =G16-I16 -> 56049 | K16: Approved for Payment | L16: Medium | M16: 46180 | N16: 46190 | O16: 46209 | P16: 46239 | Q16: =IF(AND(P16<>"",J16>0),MAX(TODAY()-P16,0),0) -> 0 | R16: R. Hassan | S16: Routine follow-up
A17: PCR-016 | B17: Operations | C17: Vertex Trading | D17: PR-2616 | E17: PO-8116 | F17: Professional services | G17: 319000 | H17: 246656 | I17: 246656 | J17: =G17-I17 -> 72344 | K17: Paid | L17: Medium | M17: 46112 | N17: 46121 | O17: 46165 | P17: 46195 | Q17: =IF(AND(P17<>"",J17>0),MAX(TODAY()-P17,0),0) -> 35 | R17: S. Ahmed | S17: Escalate overdue item
A18: PCR-017 | B18: Finance | C18: Summit Industrial | D18: PR-2617 | E18: PO-8117 | F18: Accommodation services | G18: 381000 | H18: 300554 | I18: 0 | J18: =G18-I18 -> 381000 | K18: Under Review | L18: High | M18: 46208 | N18: 46212 | O18: 46223 | P18: 46253 | Q18: =IF(AND(P18<>"",J18>0),MAX(TODAY()-P18,0),0) -> 0 | R18: F. Malik | S18: Routine follow-up
A19: PCR-018 | B19: Procurement | C19: Summit Industrial | D19: PR-2618 | E19: PO-8118 | F19: Transport services | G19: 114000 | H19: 94395 | I19: 94395 | J19: =G19-I19 -> 19605 | K19: Paid | L19: Medium | M19: 46077 | N19: 46095 | O19: 46109 | P19: 46139 | Q19: =IF(AND(P19<>"",J19>0),MAX(TODAY()-P19,0),0) -> 91 | R19: F. Malik | S19: Escalate overdue item
A20: PCR-019 | B20: Executive Office | C20: Horizon Supply | D20: PR-2619 | E20: 77 | F20: Office supplies | G20: 60000 | H20: 0 | I20: 0 | J20: =G20-I20 -> 60000 | K20: PR Approved | L20: Medium | M20: 46130 | Q20: =IF(AND(P20<>"",J20>0),MAX(TODAY()-P20,0),0) -> 0 | R20: A. Khan | S20: Routine follow-up
A21: PCR-020 | B21: Document Control | C21: Vertex Trading | D21: PR-2620 | E21: PO-8120 | F21: Site consumables | G21: 355000 | H21: 322795 | I21: 151071 | J21: =G21-I21 -> 203929 | K21: Approved for Payment | L21: Medium | M21: 46170 | N21: 46173 | O21: 46193 | P21: 46223 | Q21: =IF(AND(P21<>"",J21>0),MAX(TODAY()-P21,0),0) -> 7 | R21: F. Malik | S21: Routine follow-up
A22: PCR-021 | B22: Facilities | C22: BlueLine Services | D22: PR-2621 | E22: PO-8121 | F22: Technical materials | G22: 192000 | H22: 0 | I22: 0 | J22: =G22-I22 -> 192000 | K22: PO Issued | L22: Medium | M22: 46099 | N22: 46109 | Q22: =IF(AND(P22<>"",J22>0),MAX(TODAY()-P22,0),0) -> 0 | R22: A. Khan | S22: Routine follow-up
A23: PCR-022 | B23: Procurement | C23: Atlas Services | D23: PR-2622 | E23: PO-8122 | F23: Office supplies | G23: 121000 | H23: 111576 | I23: 111576 | J23: =G23-I23 -> 9424 | K23: Paid | L23: Medium | M23: 46140 | N23: 46150 | O23: 46190 | P23: 46220 | Q23: =IF(AND(P23<>"",J23>0),MAX(TODAY()-P23,0),0) -> 10 | R23: F. Malik | S23: Routine follow-up
A24: PCR-023 | B24: Finance | C24: Gulf Technical | D24: PR-2623 | E24: PO-8123 | F24: Equipment rental | G24: 274000 | H24: 263237 | I24: 0 | J24: =G24-I24 -> 274000 | K24: Invoice Received | L24: Medium | M24: 46152 | N24: 46169 | O24: 46205 | P24: 46235 | Q24: =IF(AND(P24<>"",J24>0),MAX(TODAY()-P24,0),0) -> 0 | R24: M. Ali | S24: Routine follow-up
A25: PCR-024 | B25: Executive Office | C25: Summit Industrial | D25: PR-2624 | E25: PO-8124 | F25: Equipment rental | G25: 44000 | H25: 43696 | I25: 0 | J25: =G25-I25 -> 44000 | K25: Invoice Received | L25: Medium | M25: 46074 | N25: 46086 | O25: 46115 | P25: 46145 | Q25: =IF(AND(P25<>"",J25>0),MAX(TODAY()-P25,0),0) -> 85 | R25: S. Ahmed | S25: Escalate overdue item
A26: PCR-025 | B26: Facilities | C26: Nexa Facilities | D26: PR-2625 | E26: PO-8125 | F26: Site consumables | G26: 262000 | H26: 211281 | I26: 0 | J26: =G26-I26 -> 262000 | K26: Under Review | L26: High | M26: 46076 | N26: 46083 | O26: 46106 | P26: 46136 | Q26: =IF(AND(P26<>"",J26>0),MAX(TODAY()-P26,0),0) -> 94 | R26: A. Khan | S26: Escalate overdue item
A27: PCR-026 | B27: Executive Office | C27: Nexa Facilities | D27: PR-2626 | E27: PO-8126 | F27: IT equipment | G27: 324000 | H27: 0 | I27: 0 | J27: =G27-I27 -> 324000 | K27: PO Issued | L27: Low | M27: 46143 | N27: 46158 | Q27: =IF(AND(P27<>"",J27>0),MAX(TODAY()-P27,0),0) -> 0 | R27: S. Ahmed | S27: Routine follow-up
A28: PCR-027 | B28: Logistics | C28: Gulf Technical | D28: PR-2627 | E28: PO-8127 | F28: Accommodation services | G28: 355000 | H28: 0 | I28: 0 | J28: =G28-I28 -> 355000 | K28: PO Issued | L28: High | M28: 46060 | N28: 46075 | Q28: =IF(AND(P28<>"",J28>0),MAX(TODAY()-P28,0),0) -> 0 | R28: R. Hassan | S28: Routine follow-up
A29: PCR-028 | B29: Document Control | C29: Nexa Facilities | D29: PR-2628 | E29: PO-8128 | F29: Maintenance works | G29: 214000 | H29: 210784 | I29: 0 | J29: =G29-I29 -> 214000 | K29: Invoice Received | L29: Medium | M29: 46169 | N29: 46177 | O29: 46197 | P29: 46227 | Q29: =IF(AND(P29<>"",J29>0),MAX(TODAY()-P29,0),0) -> 3 | R29: A. Khan | S29: Routine follow-up
A30: PCR-029 | B30: Document Control | C30: Atlas Services | D30: PR-2629 | E30: PO-8129 | F30: Maintenance works | G30: 397000 | H30: 379249 | I30: 379249 | J30: =G30-I30 -> 17751 | K30: Paid | L30: Medium | M30: 46124 | N30: 46136 | O30: 46151 | P30: 46181 | Q30: =IF(AND(P30<>"",J30>0),MAX(TODAY()-P30,0),0) -> 49 | R30: M. Ali | S30: Escalate overdue item
A31: PCR-030 | B31: Operations | C31: Vertex Trading | D31: PR-2630 | E31: 77 | F31: Transport services | G31: 118000 | H31: 0 | I31: 0 | J31: =G31-I31 -> 118000 | K31: PR Raised | L31: Low | M31: 46174 | Q31: =IF(AND(P31<>"",J31>0),MAX(TODAY()-P31,0),0) -> 0 | R31: S. Ahmed | S31: Routine follow-up
A32: PCR-031 | B32: Procurement | C32: Gulf Technical | D32: PR-2631 | E32: PO-8131 | F32: Professional services | G32: 29000 | H32: 26149 | I32: 26149 | J32: =G32-I32 -> 2851 | K32: Paid | L32: Medium | M32: 46189 | N32: 46203 | O32: 46241 | P32: 46271 | Q32: =IF(AND(P32<>"",J32>0),MAX(TODAY()-P32,0),0) -> 0 | R32: M. Ali | S32: Routine follow-up
A33: PCR-032 | B33: Facilities | C33: Prime Logistics | D33: PR-2632 | E33: PO-8132 | F33: Technical materials | G33: 219000 | H33: 191914 | I33: 0 | J33: =G33-I33 -> 219000 | K33: Under Review | L33: Medium | M33: 46053 | N33: 46065 | O33: 46101 | P33: 46131 | Q33: =IF(AND(P33<>"",J33>0),MAX(TODAY()-P33,0),0) -> 99 | R33: R. Hassan | S33: Escalate overdue item
A34: PCR-033 | B34: Executive Office | C34: Atlas Services | D34: PR-2633 | E34: PO-8133 | F34: Accommodation services | G34: 97000 | H34: 84669 | I34: 57384 | J34: =G34-I34 -> 39616 | K34: Approved for Payment | L34: High | M34: 46189 | N34: 46205 | O34: 46247 | P34: 46277 | Q34: =IF(AND(P34<>"",J34>0),MAX(TODAY()-P34,0),0) -> 0 | R34: F. Malik | S34: Routine follow-up
A35: PCR-034 | B35: Finance | C35: Prime Logistics | D35: PR-2634 | E35: PO-8134 | F35: Equipment rental | G35: 49000 | H35: 39588 | I35: 39588 | J35: =G35-I35 -> 9412 | K35: Paid | L35: High | M35: 46107 | N35: 46112 | O35: 46122 | P35: 46152 | Q35: =IF(AND(P35<>"",J35>0),MAX(TODAY()-P35,0),0) -> 78 | R35: M. Ali | S35: Escalate overdue item
A36: PCR-035 | B36: Operations | C36: Prime Logistics | D36: PR-2635 | E36: PO-8135 | F36: Site consumables | G36: 389000 | H36: 385160 | I36: 240094 | J36: =G36-I36 -> 148906 | K36: Approved for Payment | L36: Medium | M36: 46208 | N36: 46218 | O36: 46262 | P36: 46292 | Q36: =IF(AND(P36<>"",J36>0),MAX(TODAY()-P36,0),0) -> 0 | R36: M. Ali | S36: Routine follow-up
A37: PCR-036 | B37: Facilities | C37: Nexa Facilities | D37: PR-2636 | E37: PO-8136 | F37: Technical materials | G37: 179000 | H37: 170054 | I37: 0 | J37: =G37-I37 -> 179000 | K37: Invoice Received | L37: Medium | M37: 46115 | N37: 46120 | O37: 46165 | P37: 46195 | Q37: =IF(AND(P37<>"",J37>0),MAX(TODAY()-P37,0),0) -> 35 | R37: A. Khan | S37: Escalate overdue item
A38: PCR-037 | B38: Finance | C38: Gulf Technical | D38: PR-2637 | E38: PO-8137 | F38: Equipment rental | G38: 325000 | H38: 0 | I38: 0 | J38: =G38-I38 -> 325000 | K38: Delivered | L38: Low | M38: 46181 | N38: 46192 | Q38: =IF(AND(P38<>"",J38>0),MAX(TODAY()-P38,0),0) -> 0 | R38: M. Ali | S38: Routine follow-up
A39: PCR-038 | B39: Procurement | C39: Prime Logistics | D39: PR-2638 | E39: PO-8138 | F39: Technical materials | G39: 225000 | H39: 211348 | I39: 0 | J39: =G39-I39 -> 225000 | K39: Invoice Received | L39: Medium | M39: 46129 | N39: 46144 | O39: 46182 | P39: 46212 | Q39: =IF(AND(P39<>"",J39>0),MAX(TODAY()-P39,0),0) -> 18 | R39: M. Ali | S39: Routine follow-up
A40: PCR-039 | B40: Finance | C40: Prime Logistics | D40: PR-2639 | E40: PO-8139 | F40: Professional services | G40: 331000 | H40: 0 | I40: 0 | J40: =G40-I40 -> 331000 | K40: PO Issued | L40: Medium | M40: 46071 | N40: 46078 | Q40: =IF(AND(P40<>"",J40>0),MAX(TODAY()-P40,0),0) -> 0 | R40: R. Hassan | S40: Routine follow-up
...

Sheet Vendor Summary
A1: Vendor | B1: Total Commitment | C1: Invoiced | D1: Paid | E1: Outstanding | F1: Open Items
A2: Atlas Services | B2: =SUMIF('Procurement Register'!C:C,A2,'Procurement Register'!G:G) -> 1799000 | C2: =SUMIF('Procurement Register'!C:C,A2,'Procurement Register'!H:H) -> 1448474 | D2: =SUMIF('Procurement Register'!C:C,A2,'Procurement Register'!I:I) -> 577160 | E2: =SUMIF('Procurement Register'!C:C,A2,'Procurement Register'!J:J) -> 1221840 | F2: =COUNTIFS('Procurement Register'!C:C,A2,'Procurement Register'!K:K,"<>Paid") -> 8
A3: Prime Logistics | B3: =SUMIF('Procurement Register'!C:C,A3,'Procurement Register'!G:G) -> 2060000 | C3: =SUMIF('Procurement Register'!C:C,A3,'Procurement Register'!H:H) -> 1232331 | D3: =SUMIF('Procurement Register'!C:C,A3,'Procurement Register'!I:I) -> 684003 | E3: =SUMIF('Procurement Register'!C:C,A3,'Procurement Register'!J:J) -> 1375997 | F3: =COUNTIFS('Procurement Register'!C:C,A3,'Procurement Register'!K:K,"<>Paid") -> 5
A4: Gulf Technical | B4: =SUMIF('Procurement Register'!C:C,A4,'Procurement Register'!G:G) -> 2236000 | C4: =SUMIF('Procurement Register'!C:C,A4,'Procurement Register'!H:H) -> 1067872 | D4: =SUMIF('Procurement Register'!C:C,A4,'Procurement Register'!I:I) -> 607291 | E4: =SUMIF('Procurement Register'!C:C,A4,'Procurement Register'!J:J) -> 1628709 | F4: =COUNTIFS('Procurement Register'!C:C,A4,'Procurement Register'!K:K,"<>Paid") -> 5
A5: Horizon Supply | B5: =SUMIF('Procurement Register'!C:C,A5,'Procurement Register'!G:G) -> 1238000 | C5: =SUMIF('Procurement Register'!C:C,A5,'Procurement Register'!H:H) -> 636012 | D5: =SUMIF('Procurement Register'!C:C,A5,'Procurement Register'!I:I) -> 636012 | E5: =SUMIF('Procurement Register'!C:C,A5,'Procurement Register'!J:J) -> 601988 | F5: =COUNTIFS('Procurement Register'!C:C,A5,'Procurement Register'!K:K,"<>Paid") -> 3
A6: Vertex Trading | B6: =SUMIF('Procurement Register'!C:C,A6,'Procurement Register'!G:G) -> 2160000 | C6: =SUMIF('Procurement Register'!C:C,A6,'Procurement Register'!H:H) -> 772041 | D6: =SUMIF('Procurement Register'!C:C,A6,'Procurement Register'!I:I) -> 535993 | E6: =SUMIF('Procurement Register'!C:C,A6,'Procurement Register'!J:J) -> 1624007 | F6: =COUNTIFS('Procurement Register'!C:C,A6,'Procurement Register'!K:K,"<>Paid") -> 10
A7: Nexa Facilities | B7: =SUMIF('Procurement Register'!C:C,A7,'Procurement Register'!G:G) -> 2010000 | C7: =SUMIF('Procurement Register'!C:C,A7,'Procurement Register'!H:H) -> 910294 | D7: =SUMIF('Procurement Register'!C:C,A7,'Procurement Register'!I:I) -> 217243 | E7: =SUMIF('Procurement Register'!C:C,A7,'Procurement Register'!J:J) -> 1792757 | F7: =COUNTIFS('Procurement Register'!C:C,A7,'Procurement Register'!K:K,"<>Paid") -> 7
A8: Summit Industrial | B8: =SUMIF('Procurement Register'!C:C,A8,'Procurement Register'!G:G) -> 981000 | C8: =SUMIF('Procurement Register'!C:C,A8,'Procurement Register'!H:H) -> 815933 | D8: =SUMIF('Procurement Register'!C:C,A8,'Procurement Register'!I:I) -> 94395 | E8: =SUMIF('Procurement Register'!C:C,A8,'Procurement Register'!J:J) -> 886605 | F8: =COUNTIFS('Procurement Register'!C:C,A8,'Procurement Register'!K:K,"<>Paid") -> 4
A9: BlueLine Services | B9: =SUMIF('Procurement Register'!C:C,A9,'Procurement Register'!G:G) -> 681000 | C9: =SUMIF('Procurement Register'!C:C,A9,'Procurement Register'!H:H) -> 318362 | D9: =SUMIF('Procurement Register'!C:C,A9,'Procurement Register'!I:I) -> 0 | E9: =SUMIF('Procurement Register'!C:C,A9,'Procurement Register'!J:J) -> 681000 | F9: =COUNTIFS('Procurement Register'!C:C,A9,'Procurement Register'!K:K,"<>Paid") -> 3

Sheet Lists
A1: Statuses | B1: Departments | C1: Vendors
A2: PR Raised | B2: Operations | C2: Atlas Services
A3: PR Approved | B3: Administration | C3: Prime Logistics
A4: PO Issued | B4: Logistics | C4: Gulf Technical
A5: Delivered | B5: Procurement | C5: Horizon Supply
A6: Invoice Received | B6: Document Control | C6: Vertex Trading
A7: Under Review | B7: Finance | C7: Nexa Facilities
A8: Approved for Payment | B8: Executive Office | C8: Summit Industrial
A9: Paid | B9: Facilities | C9: BlueLine Services
