Workbook

Sheet Dashboard
B2: WIR Status Dashboard
B3: Coastal Tunnel Package (CTP) • Desert Horizon JV • Consultant: Meridian Engineering Partners • Demo data
B6: TOTAL WIRs | E6: APPROVED | H6: PENDING | K6: OVERDUE
B7: =COUNTA('WIR Register'!$A$5:$A$2000) | E7: =COUNTIF('WIR Register'!$H$5:$H$2000,"Approved")+COUNTIF('WIR Register'!$H$5:$H$2000,"Approved with Comments") | H7: =COUNTIF('WIR Register'!$H$5:$H$2000,"Pending") | K7: =COUNTIFS('WIR Register'!$H$5:$H$2000,"Pending",'WIR Register'!$J$5:$J$2000,">3")
B8: Submitted since July | E8: Including approved with comments | H8: Awaiting consultant response | K8: Pending more than 3 days
B10: STATUS BY DISCIPLINE | I10: MIX BY DISCIPLINE
B11: Discipline | C11: Approved | D11: With Comments | E11: Rejected | F11: Pending | G11: Total | H11: Approval %
B12: Geotechnical | C12: =COUNTIFS('WIR Register'!$C$5:$C$2000,$B12,'WIR Register'!$H$5:$H$2000,"Approved") | D12: =COUNTIFS('WIR Register'!$C$5:$C$2000,$B12,'WIR Register'!$H$5:$H$2000,"Approved with Comments") | E12: =COUNTIFS('WIR Register'!$C$5:$C$2000,$B12,'WIR Register'!$H$5:$H$2000,"Rejected") | F12: =COUNTIFS('WIR Register'!$C$5:$C$2000,$B12,'WIR Register'!$H$5:$H$2000,"Pending") | G12: =SUM(C12:F12) | H12: =IFERROR((C12+D12)/(G12-F12),0)
B13: Civil | C13: =COUNTIFS('WIR Register'!$C$5:$C$2000,$B13,'WIR Register'!$H$5:$H$2000,"Approved") | D13: =COUNTIFS('WIR Register'!$C$5:$C$2000,$B13,'WIR Register'!$H$5:$H$2000,"Approved with Comments") | E13: =COUNTIFS('WIR Register'!$C$5:$C$2000,$B13,'WIR Register'!$H$5:$H$2000,"Rejected") | F13: =COUNTIFS('WIR Register'!$C$5:$C$2000,$B13,'WIR Register'!$H$5:$H$2000,"Pending") | G13: =SUM(C13:F13) | H13: =IFERROR((C13+D13)/(G13-F13),0)
B14: Tunnelling | C14: =COUNTIFS('WIR Register'!$C$5:$C$2000,$B14,'WIR Register'!$H$5:$H$2000,"Approved") | D14: =COUNTIFS('WIR Register'!$C$5:$C$2000,$B14,'WIR Register'!$H$5:$H$2000,"Approved with Comments") | E14: =COUNTIFS('WIR Register'!$C$5:$C$2000,$B14,'WIR Register'!$H$5:$H$2000,"Rejected") | F14: =COUNTIFS('WIR Register'!$C$5:$C$2000,$B14,'WIR Register'!$H$5:$H$2000,"Pending") | G14: =SUM(C14:F14) | H14: =IFERROR((C14+D14)/(G14-F14),0)
B15: MEP | C15: =COUNTIFS('WIR Register'!$C$5:$C$2000,$B15,'WIR Register'!$H$5:$H$2000,"Approved") | D15: =COUNTIFS('WIR Register'!$C$5:$C$2000,$B15,'WIR Register'!$H$5:$H$2000,"Approved with Comments") | E15: =COUNTIFS('WIR Register'!$C$5:$C$2000,$B15,'WIR Register'!$H$5:$H$2000,"Rejected") | F15: =COUNTIFS('WIR Register'!$C$5:$C$2000,$B15,'WIR Register'!$H$5:$H$2000,"Pending") | G15: =SUM(C15:F15) | H15: =IFERROR((C15+D15)/(G15-F15),0)
B16: Survey | C16: =COUNTIFS('WIR Register'!$C$5:$C$2000,$B16,'WIR Register'!$H$5:$H$2000,"Approved") | D16: =COUNTIFS('WIR Register'!$C$5:$C$2000,$B16,'WIR Register'!$H$5:$H$2000,"Approved with Comments") | E16: =COUNTIFS('WIR Register'!$C$5:$C$2000,$B16,'WIR Register'!$H$5:$H$2000,"Rejected") | F16: =COUNTIFS('WIR Register'!$C$5:$C$2000,$B16,'WIR Register'!$H$5:$H$2000,"Pending") | G16: =SUM(C16:F16) | H16: =IFERROR((C16+D16)/(G16-F16),0)
B17: Total | C17: =SUM(C12:C16) | D17: =SUM(D12:D16) | E17: =SUM(E12:E16) | F17: =SUM(F12:F16) | G17: =SUM(G12:G16) | H17: =IFERROR((C17+D17)/(G17-F17),0)
B23: MONTHLY SUBMISSIONS | I23: MONTHLY TREND
B24: Month | C24: Geotechnical | D24: Civil | E24: Tunnelling | F24: MEP | G24: Survey | H24: Total
B25: 46204 | C25: =COUNTIFS('WIR Register'!$C$5:$C$2000,"Geotechnical",'WIR Register'!$B$5:$B$2000,">="&$B25,'WIR Register'!$B$5:$B$2000,"<="&EOMONTH($B25,0)) | D25: =COUNTIFS('WIR Register'!$C$5:$C$2000,"Civil",'WIR Register'!$B$5:$B$2000,">="&$B25,'WIR Register'!$B$5:$B$2000,"<="&EOMONTH($B25,0)) | E25: =COUNTIFS('WIR Register'!$C$5:$C$2000,"Tunnelling",'WIR Register'!$B$5:$B$2000,">="&$B25,'WIR Register'!$B$5:$B$2000,"<="&EOMONTH($B25,0)) | F25: =COUNTIFS('WIR Register'!$C$5:$C$2000,"MEP",'WIR Register'!$B$5:$B$2000,">="&$B25,'WIR Register'!$B$5:$B$2000,"<="&EOMONTH($B25,0)) | G25: =COUNTIFS('WIR Register'!$C$5:$C$2000,"Survey",'WIR Register'!$B$5:$B$2000,">="&$B25,'WIR Register'!$B$5:$B$2000,"<="&EOMONTH($B25,0)) | H25: =SUM(C25:G25)
B26: 46235 | C26: =COUNTIFS('WIR Register'!$C$5:$C$2000,"Geotechnical",'WIR Register'!$B$5:$B$2000,">="&$B26,'WIR Register'!$B$5:$B$2000,"<="&EOMONTH($B26,0)) | D26: =COUNTIFS('WIR Register'!$C$5:$C$2000,"Civil",'WIR Register'!$B$5:$B$2000,">="&$B26,'WIR Register'!$B$5:$B$2000,"<="&EOMONTH($B26,0)) | E26: =COUNTIFS('WIR Register'!$C$5:$C$2000,"Tunnelling",'WIR Register'!$B$5:$B$2000,">="&$B26,'WIR Register'!$B$5:$B$2000,"<="&EOMONTH($B26,0)) | F26: =COUNTIFS('WIR Register'!$C$5:$C$2000,"MEP",'WIR Register'!$B$5:$B$2000,">="&$B26,'WIR Register'!$B$5:$B$2000,"<="&EOMONTH($B26,0)) | G26: =COUNTIFS('WIR Register'!$C$5:$C$2000,"Survey",'WIR Register'!$B$5:$B$2000,">="&$B26,'WIR Register'!$B$5:$B$2000,"<="&EOMONTH($B26,0)) | H26: =SUM(C26:G26)
B27: 46266 | C27: =COUNTIFS('WIR Register'!$C$5:$C$2000,"Geotechnical",'WIR Register'!$B$5:$B$2000,">="&$B27,'WIR Register'!$B$5:$B$2000,"<="&EOMONTH($B27,0)) | D27: =COUNTIFS('WIR Register'!$C$5:$C$2000,"Civil",'WIR Register'!$B$5:$B$2000,">="&$B27,'WIR Register'!$B$5:$B$2000,"<="&EOMONTH($B27,0)) | E27: =COUNTIFS('WIR Register'!$C$5:$C$2000,"Tunnelling",'WIR Register'!$B$5:$B$2000,">="&$B27,'WIR Register'!$B$5:$B$2000,"<="&EOMONTH($B27,0)) | F27: =COUNTIFS('WIR Register'!$C$5:$C$2000,"MEP",'WIR Register'!$B$5:$B$2000,">="&$B27,'WIR Register'!$B$5:$B$2000,"<="&EOMONTH($B27,0)) | G27: =COUNTIFS('WIR Register'!$C$5:$C$2000,"Survey",'WIR Register'!$B$5:$B$2000,">="&$B27,'WIR Register'!$B$5:$B$2000,"<="&EOMONTH($B27,0)) | H27: =SUM(C27:G27)
B28: 46296 | C28: =COUNTIFS('WIR Register'!$C$5:$C$2000,"Geotechnical",'WIR Register'!$B$5:$B$2000,">="&$B28,'WIR Register'!$B$5:$B$2000,"<="&EOMONTH($B28,0)) | D28: =COUNTIFS('WIR Register'!$C$5:$C$2000,"Civil",'WIR Register'!$B$5:$B$2000,">="&$B28,'WIR Register'!$B$5:$B$2000,"<="&EOMONTH($B28,0)) | E28: =COUNTIFS('WIR Register'!$C$5:$C$2000,"Tunnelling",'WIR Register'!$B$5:$B$2000,">="&$B28,'WIR Register'!$B$5:$B$2000,"<="&EOMONTH($B28,0)) | F28: =COUNTIFS('WIR Register'!$C$5:$C$2000,"MEP",'WIR Register'!$B$5:$B$2000,">="&$B28,'WIR Register'!$B$5:$B$2000,"<="&EOMONTH($B28,0)) | G28: =COUNTIFS('WIR Register'!$C$5:$C$2000,"Survey",'WIR Register'!$B$5:$B$2000,">="&$B28,'WIR Register'!$B$5:$B$2000,"<="&EOMONTH($B28,0)) | H28: =SUM(C28:G28)

Sheet WIR Register
A1: WIR Register – Work Inspection Requests
A2: Coastal Tunnel Package (CTP) – Desert Horizon JV • Consultant: Meridian Engineering Partners • Demo data
A4: WIR No. | B4: Submitted | C4: Discipline | D4: Activity | E4: Location | F4: Inspection Date | G4: Consultant Inspector | H4: Status | I4: Response Date | J4: Days Open | K4: Remarks
A5: CTP-WIR-CIV-0001 | B5: 46204 | C5: Civil | D5: Formwork inspection | E5: CH 6+071 | F5: 46205 | G5: Eng. Ali Haddad | H5: Approved | I5: 46207 | J5: =IF(H5="Pending",TODAY()-B5,IF(I5="","",I5-B5))
A6: CTP-WIR-GEO-0001 | B6: 46204 | C6: Geotechnical | D6: Borehole drilling & logging | E6: CH 1+840 | F6: 46205 | G6: Eng. Sara Nasser | H6: Approved | I6: 46205 | J6: =IF(H6="Pending",TODAY()-B6,IF(I6="","",I6-B6))
A7: CTP-WIR-MEP-0001 | B7: 46204 | C7: MEP | D7: Ventilation duct alignment | E7: CH 8+879 | F7: 46204 | G7: Eng. Sara Nasser | H7: Rejected | I7: 46204 | J7: =IF(H7="Pending",TODAY()-B7,IF(I7="","",I7-B7)) | K7: Re-inspection required
A8: CTP-WIR-SUR-0001 | B8: 46204 | C8: Survey | D8: Setting-out check | E8: CH 2+105 | F8: 46204 | G8: Eng. Sara Nasser | H8: Approved | I8: 46207 | J8: =IF(H8="Pending",TODAY()-B8,IF(I8="","",I8-B8))
A9: CTP-WIR-TUN-0001 | B9: 46204 | C9: Tunnelling | D9: Segment ring build | E9: CH 3+645 | F9: 46204 | G9: Eng. Hana Saleh | H9: Approved with Comments | I9: 46204 | J9: =IF(H9="Pending",TODAY()-B9,IF(I9="","",I9-B9)) | K9: Minor comments to close
A10: CTP-WIR-CIV-0002 | B10: 46205 | C10: Civil | D10: Concrete pouring | E10: CH 8+437 | F10: 46205 | G10: Eng. Pedro Alves | H10: Approved | I10: 46207 | J10: =IF(H10="Pending",TODAY()-B10,IF(I10="","",I10-B10))
A11: CTP-WIR-CIV-0003 | B11: 46205 | C11: Civil | D11: Formwork inspection | E11: CH 2+715 | F11: 46207 | G11: Eng. Ali Haddad | H11: Approved | I11: 46208 | J11: =IF(H11="Pending",TODAY()-B11,IF(I11="","",I11-B11))
A12: CTP-WIR-MEP-0002 | B12: 46205 | C12: MEP | D12: Cable tray installation | E12: CH 7+431 | F12: 46206 | G12: Eng. Ali Haddad | H12: Approved with Comments | I12: 46207 | J12: =IF(H12="Pending",TODAY()-B12,IF(I12="","",I12-B12)) | K12: Minor comments to close
A13: CTP-WIR-SUR-0002 | B13: 46205 | C13: Survey | D13: Settlement monitoring | E13: CH 9+508 | F13: 46206 | G13: Eng. Ali Haddad | H13: Approved | I13: 46207 | J13: =IF(H13="Pending",TODAY()-B13,IF(I13="","",I13-B13))
A14: CTP-WIR-SUR-0003 | B14: 46205 | C14: Survey | D14: As-built survey | E14: CH 1+062 | F14: 46205 | G14: Eng. Hana Saleh | H14: Rejected | I14: 46207 | J14: =IF(H14="Pending",TODAY()-B14,IF(I14="","",I14-B14)) | K14: Re-inspection required
A15: CTP-WIR-TUN-0002 | B15: 46205 | C15: Tunnelling | D15: Segment ring build | E15: CH 4+623 | F15: 46207 | G15: Eng. Ali Haddad | H15: Approved with Comments | I15: 46209 | J15: =IF(H15="Pending",TODAY()-B15,IF(I15="","",I15-B15)) | K15: Minor comments to close
A16: CTP-WIR-CIV-0004 | B16: 46207 | C16: Civil | D16: Backfilling & compaction | E16: CH 4+723 | F16: 46208 | G16: Eng. Sara Nasser | H16: Approved with Comments | I16: 46211 | J16: =IF(H16="Pending",TODAY()-B16,IF(I16="","",I16-B16)) | K16: Minor comments to close
A17: CTP-WIR-GEO-0002 | B17: 46207 | C17: Geotechnical | D17: Ground anchor installation | E17: CH 5+023 | F17: 46209 | G17: Eng. Sara Nasser | H17: Approved | I17: 46211 | J17: =IF(H17="Pending",TODAY()-B17,IF(I17="","",I17-B17))
A18: CTP-WIR-GEO-0003 | B18: 46207 | C18: Geotechnical | D18: Rock bolt pull-out test | E18: CH 0+223 | F18: 46208 | G18: Eng. Mark Collins | H18: Approved | I18: 46210 | J18: =IF(H18="Pending",TODAY()-B18,IF(I18="","",I18-B18))
A19: CTP-WIR-GEO-0004 | B19: 46207 | C19: Geotechnical | D19: Ground anchor installation | E19: CH 1+170 | F19: 46208 | G19: Eng. Pedro Alves | H19: Approved | I19: 46210 | J19: =IF(H19="Pending",TODAY()-B19,IF(I19="","",I19-B19))
A20: CTP-WIR-SUR-0004 | B20: 46207 | C20: Survey | D20: Tunnel alignment survey | E20: CH 9+670 | F20: 46208 | G20: Eng. Pedro Alves | H20: Rejected | I20: 46211 | J20: =IF(H20="Pending",TODAY()-B20,IF(I20="","",I20-B20)) | K20: Re-inspection required
A21: CTP-WIR-TUN-0003 | B21: 46207 | C21: Tunnelling | D21: TBM cutter change | E21: CH 1+180 | F21: 46209 | G21: Eng. Mark Collins | H21: Rejected | I21: 46210 | J21: =IF(H21="Pending",TODAY()-B21,IF(I21="","",I21-B21)) | K21: Re-inspection required
A22: CTP-WIR-TUN-0004 | B22: 46207 | C22: Tunnelling | D22: Annulus grouting | E22: CH 2+269 | F22: 46208 | G22: Eng. Ali Haddad | H22: Approved | I22: 46211 | J22: =IF(H22="Pending",TODAY()-B22,IF(I22="","",I22-B22))
A23: CTP-WIR-CIV-0005 | B23: 46208 | C23: Civil | D23: Concrete pouring | E23: CH 8+103 | F23: 46208 | G23: Eng. Hana Saleh | H23: Approved | I23: 46209 | J23: =IF(H23="Pending",TODAY()-B23,IF(I23="","",I23-B23))
A24: CTP-WIR-GEO-0005 | B24: 46208 | C24: Geotechnical | D24: Ground anchor installation | E24: CH 1+493 | F24: 46210 | G24: Eng. Ali Haddad | H24: Approved | I24: 46212 | J24: =IF(H24="Pending",TODAY()-B24,IF(I24="","",I24-B24))
A25: CTP-WIR-GEO-0006 | B25: 46208 | C25: Geotechnical | D25: Borehole drilling & logging | E25: CH 7+166 | F25: 46209 | G25: Eng. Sara Nasser | H25: Approved | I25: 46210 | J25: =IF(H25="Pending",TODAY()-B25,IF(I25="","",I25-B25))
A26: CTP-WIR-MEP-0003 | B26: 46208 | C26: MEP | D26: Pump station testing | E26: CH 5+616 | F26: 46210 | G26: Eng. Pedro Alves | H26: Approved | I26: 46211 | J26: =IF(H26="Pending",TODAY()-B26,IF(I26="","",I26-B26))
A27: CTP-WIR-MEP-0004 | B27: 46208 | C27: MEP | D27: Lighting installation | E27: CH 7+491 | F27: 46208 | G27: Eng. Sara Nasser | H27: Approved | I27: 46210 | J27: =IF(H27="Pending",TODAY()-B27,IF(I27="","",I27-B27))
A28: CTP-WIR-CIV-0006 | B28: 46209 | C28: Civil | D28: Formwork inspection | E28: CH 8+023 | F28: 46210 | G28: Eng. Hana Saleh | H28: Approved | I28: 46211 | J28: =IF(H28="Pending",TODAY()-B28,IF(I28="","",I28-B28))
A29: CTP-WIR-MEP-0005 | B29: 46209 | C29: MEP | D29: Pump station testing | E29: CH 8+554 | F29: 46210 | G29: Eng. Mark Collins | H29: Approved | I29: 46211 | J29: =IF(H29="Pending",TODAY()-B29,IF(I29="","",I29-B29))
A30: CTP-WIR-SUR-0005 | B30: 46209 | C30: Survey | D30: Settlement monitoring | E30: CH 3+204 | F30: 46210 | G30: Eng. Sara Nasser | H30: Approved with Comments | I30: 46212 | J30: =IF(H30="Pending",TODAY()-B30,IF(I30="","",I30-B30)) | K30: Minor comments to close
A31: CTP-WIR-TUN-0005 | B31: 46209 | C31: Tunnelling | D31: Annulus grouting | E31: CH 1+712 | F31: 46209 | G31: Eng. Hana Saleh | H31: Approved with Comments | I31: 46210 | J31: =IF(H31="Pending",TODAY()-B31,IF(I31="","",I31-B31)) | K31: Minor comments to close
A32: CTP-WIR-CIV-0007 | B32: 46210 | C32: Civil | D32: Rebar inspection before concrete | E32: CH 9+860 | F32: 46211 | G32: Eng. Pedro Alves | H32: Approved | I32: 46214 | J32: =IF(H32="Pending",TODAY()-B32,IF(I32="","",I32-B32))
A33: CTP-WIR-GEO-0007 | B33: 46210 | C33: Geotechnical | D33: Rock bolt pull-out test | E33: CH 4+198 | F33: 46210 | G33: Eng. Pedro Alves | H33: Approved with Comments | I33: 46212 | J33: =IF(H33="Pending",TODAY()-B33,IF(I33="","",I33-B33)) | K33: Minor comments to close
A34: CTP-WIR-GEO-0008 | B34: 46210 | C34: Geotechnical | D34: Borehole drilling & logging | E34: CH 1+225 | F34: 46211 | G34: Eng. Mark Collins | H34: Rejected | I34: 46212 | J34: =IF(H34="Pending",TODAY()-B34,IF(I34="","",I34-B34)) | K34: Re-inspection required
A35: CTP-WIR-SUR-0006 | B35: 46210 | C35: Survey | D35: As-built survey | E35: CH 7+673 | F35: 46211 | G35: Eng. Mark Collins | H35: Approved | I35: 46214 | J35: =IF(H35="Pending",TODAY()-B35,IF(I35="","",I35-B35))
A36: CTP-WIR-SUR-0007 | B36: 46210 | C36: Survey | D36: Setting-out check | E36: CH 8+767 | F36: 46211 | G36: Eng. Pedro Alves | H36: Approved | I36: 46211 | J36: =IF(H36="Pending",TODAY()-B36,IF(I36="","",I36-B36))
A37: CTP-WIR-TUN-0006 | B37: 46210 | C37: Tunnelling | D37: Tunnel invert cleaning | E37: CH 1+931 | F37: 46211 | G37: Eng. Mark Collins | H37: Approved with Comments | I37: 46211 | J37: =IF(H37="Pending",TODAY()-B37,IF(I37="","",I37-B37)) | K37: Minor comments to close
A38: CTP-WIR-TUN-0007 | B38: 46210 | C38: Tunnelling | D38: Tunnel invert cleaning | E38: CH 5+088 | F38: 46212 | G38: Eng. Pedro Alves | H38: Approved with Comments | I38: 46214 | J38: =IF(H38="Pending",TODAY()-B38,IF(I38="","",I38-B38)) | K38: Minor comments to close
A39: CTP-WIR-TUN-0008 | B39: 46210 | C39: Tunnelling | D39: TBM cutter change | E39: CH 2+174 | F39: 46212 | G39: Eng. Ali Haddad | H39: Approved with Comments | I39: 46212 | J39: =IF(H39="Pending",TODAY()-B39,IF(I39="","",I39-B39)) | K39: Minor comments to close
A40: CTP-WIR-GEO-0009 | B40: 46211 | C40: Geotechnical | D40: Grout injection | E40: CH 0+257 | F40: 46212 | G40: Eng. Sara Nasser | H40: Approved with Comments | I40: 46213 | J40: =IF(H40="Pending",TODAY()-B40,IF(I40="","",I40-B40)) | K40: Minor comments to close
A41: CTP-WIR-GEO-0010 | B41: 46211 | C41: Geotechnical | D41: Ground anchor installation | E41: CH 4+557 | F41: 46212 | G41: Eng. Mark Collins | H41: Approved with Comments | I41: 46213 | J41: =IF(H41="Pending",TODAY()-B41,IF(I41="","",I41-B41)) | K41: Minor comments to close
...

Sheet Daily Log
A1: Daily WIR Submission Log
A2: Submitted per discipline per working day (Friday off) • Formulas count directly from the WIR Register
A4: Date | B4: Day | C4: Geotechnical | D4: Civil | E4: Tunnelling | F4: MEP | G4: Survey | H4: Total
A5: 46309 | B5: =TEXT(A5,"ddd") | C5: =COUNTIFS('WIR Register'!$B$5:$B$2000,$A5,'WIR Register'!$C$5:$C$2000,"Geotechnical") | D5: =COUNTIFS('WIR Register'!$B$5:$B$2000,$A5,'WIR Register'!$C$5:$C$2000,"Civil") | E5: =COUNTIFS('WIR Register'!$B$5:$B$2000,$A5,'WIR Register'!$C$5:$C$2000,"Tunnelling") | F5: =COUNTIFS('WIR Register'!$B$5:$B$2000,$A5,'WIR Register'!$C$5:$C$2000,"MEP") | G5: =COUNTIFS('WIR Register'!$B$5:$B$2000,$A5,'WIR Register'!$C$5:$C$2000,"Survey") | H5: =SUM(C5:G5)
A6: 46308 | B6: =TEXT(A6,"ddd") | C6: =COUNTIFS('WIR Register'!$B$5:$B$2000,$A6,'WIR Register'!$C$5:$C$2000,"Geotechnical") | D6: =COUNTIFS('WIR Register'!$B$5:$B$2000,$A6,'WIR Register'!$C$5:$C$2000,"Civil") | E6: =COUNTIFS('WIR Register'!$B$5:$B$2000,$A6,'WIR Register'!$C$5:$C$2000,"Tunnelling") | F6: =COUNTIFS('WIR Register'!$B$5:$B$2000,$A6,'WIR Register'!$C$5:$C$2000,"MEP") | G6: =COUNTIFS('WIR Register'!$B$5:$B$2000,$A6,'WIR Register'!$C$5:$C$2000,"Survey") | H6: =SUM(C6:G6)
A7: 46307 | B7: =TEXT(A7,"ddd") | C7: =COUNTIFS('WIR Register'!$B$5:$B$2000,$A7,'WIR Register'!$C$5:$C$2000,"Geotechnical") | D7: =COUNTIFS('WIR Register'!$B$5:$B$2000,$A7,'WIR Register'!$C$5:$C$2000,"Civil") | E7: =COUNTIFS('WIR Register'!$B$5:$B$2000,$A7,'WIR Register'!$C$5:$C$2000,"Tunnelling") | F7: =COUNTIFS('WIR Register'!$B$5:$B$2000,$A7,'WIR Register'!$C$5:$C$2000,"MEP") | G7: =COUNTIFS('WIR Register'!$B$5:$B$2000,$A7,'WIR Register'!$C$5:$C$2000,"Survey") | H7: =SUM(C7:G7)
A8: 46306 | B8: =TEXT(A8,"ddd") | C8: =COUNTIFS('WIR Register'!$B$5:$B$2000,$A8,'WIR Register'!$C$5:$C$2000,"Geotechnical") | D8: =COUNTIFS('WIR Register'!$B$5:$B$2000,$A8,'WIR Register'!$C$5:$C$2000,"Civil") | E8: =COUNTIFS('WIR Register'!$B$5:$B$2000,$A8,'WIR Register'!$C$5:$C$2000,"Tunnelling") | F8: =COUNTIFS('WIR Register'!$B$5:$B$2000,$A8,'WIR Register'!$C$5:$C$2000,"MEP") | G8: =COUNTIFS('WIR Register'!$B$5:$B$2000,$A8,'WIR Register'!$C$5:$C$2000,"Survey") | H8: =SUM(C8:G8)
A9: 46305 | B9: =TEXT(A9,"ddd") | C9: =COUNTIFS('WIR Register'!$B$5:$B$2000,$A9,'WIR Register'!$C$5:$C$2000,"Geotechnical") | D9: =COUNTIFS('WIR Register'!$B$5:$B$2000,$A9,'WIR Register'!$C$5:$C$2000,"Civil") | E9: =COUNTIFS('WIR Register'!$B$5:$B$2000,$A9,'WIR Register'!$C$5:$C$2000,"Tunnelling") | F9: =COUNTIFS('WIR Register'!$B$5:$B$2000,$A9,'WIR Register'!$C$5:$C$2000,"MEP") | G9: =COUNTIFS('WIR Register'!$B$5:$B$2000,$A9,'WIR Register'!$C$5:$C$2000,"Survey") | H9: =SUM(C9:G9)
A10: 46303 | B10: =TEXT(A10,"ddd") | C10: =COUNTIFS('WIR Register'!$B$5:$B$2000,$A10,'WIR Register'!$C$5:$C$2000,"Geotechnical") | D10: =COUNTIFS('WIR Register'!$B$5:$B$2000,$A10,'WIR Register'!$C$5:$C$2000,"Civil") | E10: =COUNTIFS('WIR Register'!$B$5:$B$2000,$A10,'WIR Register'!$C$5:$C$2000,"Tunnelling") | F10: =COUNTIFS('WIR Register'!$B$5:$B$2000,$A10,'WIR Register'!$C$5:$C$2000,"MEP") | G10: =COUNTIFS('WIR Register'!$B$5:$B$2000,$A10,'WIR Register'!$C$5:$C$2000,"Survey") | H10: =SUM(C10:G10)
A11: 46302 | B11: =TEXT(A11,"ddd") | C11: =COUNTIFS('WIR Register'!$B$5:$B$2000,$A11,'WIR Register'!$C$5:$C$2000,"Geotechnical") | D11: =COUNTIFS('WIR Register'!$B$5:$B$2000,$A11,'WIR Register'!$C$5:$C$2000,"Civil") | E11: =COUNTIFS('WIR Register'!$B$5:$B$2000,$A11,'WIR Register'!$C$5:$C$2000,"Tunnelling") | F11: =COUNTIFS('WIR Register'!$B$5:$B$2000,$A11,'WIR Register'!$C$5:$C$2000,"MEP") | G11: =COUNTIFS('WIR Register'!$B$5:$B$2000,$A11,'WIR Register'!$C$5:$C$2000,"Survey") | H11: =SUM(C11:G11)
A12: 46301 | B12: =TEXT(A12,"ddd") | C12: =COUNTIFS('WIR Register'!$B$5:$B$2000,$A12,'WIR Register'!$C$5:$C$2000,"Geotechnical") | D12: =COUNTIFS('WIR Register'!$B$5:$B$2000,$A12,'WIR Register'!$C$5:$C$2000,"Civil") | E12: =COUNTIFS('WIR Register'!$B$5:$B$2000,$A12,'WIR Register'!$C$5:$C$2000,"Tunnelling") | F12: =COUNTIFS('WIR Register'!$B$5:$B$2000,$A12,'WIR Register'!$C$5:$C$2000,"MEP") | G12: =COUNTIFS('WIR Register'!$B$5:$B$2000,$A12,'WIR Register'!$C$5:$C$2000,"Survey") | H12: =SUM(C12:G12)
A13: 46300 | B13: =TEXT(A13,"ddd") | C13: =COUNTIFS('WIR Register'!$B$5:$B$2000,$A13,'WIR Register'!$C$5:$C$2000,"Geotechnical") | D13: =COUNTIFS('WIR Register'!$B$5:$B$2000,$A13,'WIR Register'!$C$5:$C$2000,"Civil") | E13: =COUNTIFS('WIR Register'!$B$5:$B$2000,$A13,'WIR Register'!$C$5:$C$2000,"Tunnelling") | F13: =COUNTIFS('WIR Register'!$B$5:$B$2000,$A13,'WIR Register'!$C$5:$C$2000,"MEP") | G13: =COUNTIFS('WIR Register'!$B$5:$B$2000,$A13,'WIR Register'!$C$5:$C$2000,"Survey") | H13: =SUM(C13:G13)
A14: 46299 | B14: =TEXT(A14,"ddd") | C14: =COUNTIFS('WIR Register'!$B$5:$B$2000,$A14,'WIR Register'!$C$5:$C$2000,"Geotechnical") | D14: =COUNTIFS('WIR Register'!$B$5:$B$2000,$A14,'WIR Register'!$C$5:$C$2000,"Civil") | E14: =COUNTIFS('WIR Register'!$B$5:$B$2000,$A14,'WIR Register'!$C$5:$C$2000,"Tunnelling") | F14: =COUNTIFS('WIR Register'!$B$5:$B$2000,$A14,'WIR Register'!$C$5:$C$2000,"MEP") | G14: =COUNTIFS('WIR Register'!$B$5:$B$2000,$A14,'WIR Register'!$C$5:$C$2000,"Survey") | H14: =SUM(C14:G14)
A15: 46298 | B15: =TEXT(A15,"ddd") | C15: =COUNTIFS('WIR Register'!$B$5:$B$2000,$A15,'WIR Register'!$C$5:$C$2000,"Geotechnical") | D15: =COUNTIFS('WIR Register'!$B$5:$B$2000,$A15,'WIR Register'!$C$5:$C$2000,"Civil") | E15: =COUNTIFS('WIR Register'!$B$5:$B$2000,$A15,'WIR Register'!$C$5:$C$2000,"Tunnelling") | F15: =COUNTIFS('WIR Register'!$B$5:$B$2000,$A15,'WIR Register'!$C$5:$C$2000,"MEP") | G15: =COUNTIFS('WIR Register'!$B$5:$B$2000,$A15,'WIR Register'!$C$5:$C$2000,"Survey") | H15: =SUM(C15:G15)
A16: 46296 | B16: =TEXT(A16,"ddd") | C16: =COUNTIFS('WIR Register'!$B$5:$B$2000,$A16,'WIR Register'!$C$5:$C$2000,"Geotechnical") | D16: =COUNTIFS('WIR Register'!$B$5:$B$2000,$A16,'WIR Register'!$C$5:$C$2000,"Civil") | E16: =COUNTIFS('WIR Register'!$B$5:$B$2000,$A16,'WIR Register'!$C$5:$C$2000,"Tunnelling") | F16: =COUNTIFS('WIR Register'!$B$5:$B$2000,$A16,'WIR Register'!$C$5:$C$2000,"MEP") | G16: =COUNTIFS('WIR Register'!$B$5:$B$2000,$A16,'WIR Register'!$C$5:$C$2000,"Survey") | H16: =SUM(C16:G16)
... A95: 46204 | B95: =TEXT(A95,"ddd") | C95: =COUNTIFS('WIR Register'!$B$5:$B$2000,$A95,'WIR Register'!$C$5:$C$2000,"Geotechnical") | D95: =COUNTIFS('WIR Register'!$B$5:$B$2000,$A95,'WIR Register'!$C$5:$C$2000,"Civil") | E95: =COUNTIFS('WIR Register'!$B$5:$B$2000,$A95,'WIR Register'!$C$5:$C$2000,"Tunnelling") | F95: =COUNTIFS('WIR Register'!$B$5:$B$2000,$A95,'WIR Register'!$C$5:$C$2000,"MEP") | G95: =COUNTIFS('WIR Register'!$B$5:$B$2000,$A95,'WIR Register'!$C$5:$C$2000,"Survey") | H95: =SUM(C95:G95)
